Workbook

Sheet CHANGELOG_rev0_6
B2: L6790 design spreadsheet r1.0 - corrections applied (design guide rev 0.6)
B3: Every change below is documented as a cell comment in place. Open in Excel and press Ctrl+Alt+F9 to force a full recalculation.
B5: Sheet | C5: Cell | D5: Was | E5: Now | F5: Why
B6: Design Spec | C6: D20 | D6: =IF('Design Spec'!D80=0,IF(2*D13>IF(165>D14/2,165,D14/2),_xlfn.CONCAT(IF(165>D14/2,165,_xlfn.FLOOR.MATH(D14/2)),"-",2*D13),2*D13),D13) | E6: =MIN(2*D13,245/SQRT(2)) | F6: C.8 : with morphing the worst LOW equivalent input is the HB side of the morphing threshold, VHVPK_BIH/sqrt2 = 173.24 Vac - not a 165..180 range.
B7: Design Spec | C7: F20 | D7: 180 | E7: =D20 | F7: C.8 : selected value must follow the corrected D20 (173.24 Vac).
B8: Design Spec | C8: D81 | D8: None | E8: =2*235/SQRT(2) | F8: C.8 NEW : highest equivalent input = FB side of the morphing threshold, 2*VHVPK_BOH/sqrt2 = 332.34 Vac. This corner fixes the MAXIMUM operating frequency (240.9 kHz), which the tool never evaluates.
B9: Res. Tank Design | C9: D9 | D9: =(SQRT(2)*'Design Spec'!D89)/(2*(('Design Spec'!D95+'Design Spec'!D107*'Design Spec'!D106)/'Design Spec'!D107)) | E9: =(SQRT(2)*'Design Spec'!D89)/(2*('Design Spec'!D95+'Design Spec'!D107*'Design Spec'!D106)) | F9: C.5 : the rectifier drop is already counted Nrect times in the numerator; dividing by Nrect again doubles n. Physical Np/Ns = n*Vo.eff/(Vout+Nrect*Vrect).
B10: Res. Tank Design | C10: F9 | D10: 5 | E10: 2.5 | F10: C.5 : selected turns ratio follows the corrected D9 (2.519 -> 2.5).
B11: Res. Tank Design | C11: D10 | D11: =2*IF(F9,F9,D9)*(('Design Spec'!D95+'Design Spec'!D107*'Design Spec'!D106)/'Design Spec'!D107)/(SQRT(2)*'Design Spec'!D83) | E11: =2*IF(F9,F9,D9)*(('Design Spec'!D95+'Design Spec'!D107*'Design Spec'!D106))/(SQRT(2)*'Design Spec'!D83) | F11: C.5 : reflected output voltage is (Vout+Nrect*Vrect), not divided by Nrect.
B12: Res. Tank Design | C12: D11 | D12: =2*IF(F9,F9,D9)*(('Design Spec'!D95+'Design Spec'!D107*'Design Spec'!D106)/'Design Spec'!D107)/(SQRT(2)*'Design Spec'!D79) | E12: =2*IF(F9,F9,D9)*(('Design Spec'!D95+'Design Spec'!D107*'Design Spec'!D106))/(SQRT(2)*'Design Spec'!D79) | F12: C.5 : reflected output voltage is (Vout+Nrect*Vrect), not divided by Nrect.
B13: Res. Tank Design | C13: D17 | D13: =((IF(F9,F9,D9))^2)*(4/((PI())^2))*(((('Design Spec'!D95+'Design Spec'!D107*'Design Spec'!D106)/'Design Spec'!D107)^2)/('Preliminary Calculation'!D10)) | E13: =((IF(F9,F9,D9))^2)*(4/((PI())^2))*(((('Design Spec'!D95+'Design Spec'!D107*'Design Spec'!D106))^2)/('Preliminary Calculation'!D10)) | F13: C.5 : reflected output voltage is (Vout+Nrect*Vrect), not divided by Nrect.
B14: Res. Tank Design | C14: D20 | D14: =((SQRT((D16*(1+D16))))/(2*IF(F9,F9,D9)))*((SQRT(2)*'Design Spec'!D83)/((('Design Spec'!D95+'Design Spec'!D107*'Design Spec'!D106)/'Design Spec'!D107))) | E14: =((SQRT((D16*(1+D16))))/(2*IF(F9,F9,D9)))*((SQRT(2)*'Design Spec'!D83)/((('Design Spec'!D95+'Design Spec'!D107*'Design Spec'!D106)))) | F14: C.5 : reflected output voltage is (Vout+Nrect*Vrect), not divided by Nrect.
B15: Res. Tank Design | C15: D35 | D15: =(PI()*'Design Spec'!D98)/(SQRT(2)*('Preliminary Calculation'!D17/100)*'Design Spec'!D83*COS('Res. Tank Design'!D29)) | E15: =(2*PI()*'Design Spec'!D98)/(SQRT(2)*('Preliminary Calculation'!D17/100)*'Design Spec'!D83*COS('Res. Tank Design'!D29)) | F15: C.6 : at the line peak the instantaneous tank power is 2*Pout, not Pout. The tool value is exactly half.
B16: Res. Tank Design | C16: D60 | D16: =(SQRT(2*(('Design Spec'!D111*(10^-12))/((IF(F44,F44,D44)+IF(F45,F45,D45))*(10^-6)))))*('Design Spec'!D83) | E16: =(SQRT(2*(('Design Spec'!D111*(10^-12))/((IF(F44,F44,D44)+IF(F45,F45,D45))*(10^-6)))))*(SQRT(2)*'Design Spec'!D83) | F16: C.6 : Vin must be the PEAK, not the rms value.
... B35: RTC | C35: 2803 cells, rows 16-18, 41-46, 53-58, 67-72, 81-86, 95-107 | D35: (Vout+Nrect*Vrect)/Nrect | E35: (Vout+Nrect*Vrect) | F35: C.5 propagated. The RTC gain and Q grid carries its own copy of the reflected output voltage and divided it by Nrect a second time. Left unfixed, the corrected n = 2.5 halves every gain in the grid and the whole sheet returns #NUM.
B37: NOT fixable by a cell edit - structural limits of the workbook
B38: RTC!25/26 - the fn search grid stops at fn.max = sqrt(lambda/(1+lambda-1/M.Vmax.pk)) = 1.3703 (205.9 kHz). The real full-load operating point at the FB morphing threshold sits at fn = 1.603 (240.9 kHz) and simply cannot be represented. Device Setting!D2 therefore still reports 187 kHz.
B40: CC rows 20-31 evaluate only theta = pi/4, pi/3, pi/2. Eq.[70a] (output-capacitor rms) and the mains-cycle rms currents need an average over the whole half line cycle.
B42: Design Spec!D33/34/37 - the OutCap_Sel_DB auto-selection result is referenced by no cell; Power Components uses manual entries only, with no warning when the two disagree.
B44: Design Spec!D48 (Cp = 2 nF) is a dead input cell, referenced nowhere.
B46: Power Components!D77 - C.tot = 2*Coss + Cpar is never fed back into Design Spec!D46 (c.HB), so eq.[116] iteration does not happen.
B48: Device Setting!B113 - the 'Split resonant capacitors for forced HB configuration' clause has a heading but no content (DS 5.3.1 requires two Cr/2 capacitors in that configuration).
B50: Res. Tank Design!D9 vs D51 - n is labelled 'Physical Turn Ratio' and n.T 'Real Turn Ratio' at the same time. Only one of them can be the ratio you actually wind (guide 3.10).
B51: ADDED 2026-08-21 - ISEN (pin 6) block, guide eq. [79] [81] [84]. None of these five were touched by rev 0.6.
B52: Device Setting | C52: D32 | D52: =CC!E27 (= I.trafo.pk only) | E52: =IF(z>=1,CC!E28,CC!E28*(2*ACOS(-z)/PI()-1)+CC!E27*SQRT(1-z^2)), z=2*CC!E28/(PI()*CC!E27) | F52: C.14 (guide eq.[79]): R.CS is in the bridge return and sees the COMPOSITE tank current, load component plus magnetizing component. The cell is named Ilr.pk.max but was wired to I.trafo.pk, which is about 10 % low, so R.CS.max2 came out about 10 % too permissive. Closed form: the peak of I.Lm.pk*(2x-1)+I.trafo.pk*sin(pi*x) is at cos(pi*x)=-z.
B53: Device Setting | C53: D33 | D53: =MAX(CC!C29,'Preliminary Calculation'!D11) | E53: =MAX(CC!E29,'Preliminary Calculation'!D11) | F53: C.16: CC!C29 is the switching-period rms at theta = pi/4 only - neither the line-cycle rms (the physically correct basis for dissipation) nor the worst switching period. Guide eq.[81] and its worked example use the worst switching period, CC!E29 at theta = pi/2. Conservative, and it makes the parallel-resistor count honest.
B54: Device Setting | C54: D45 | D54: =D43*(3/220+1/440)^-1 (= 188.571 mOhm, constant) | E54: =D44 | F54: C.15: this was not a calculation. (3/220+1/440)^-1 = 62.857 mOhm is the EVL board network 220||220||220||(220+220) written as a conductance sum; multiplying by D43 only cancelled the /D43 on the next row, so R.CS stayed 62.857 mOhm whatever the design. It also exceeded its own ceiling D44 without any warning once the spec changed. D45 is now the calculated maximum single resistor and F45 holds the selection.
B55: Device Setting | C55: F45 / D43 / D46 | D55: text "220||220||220||(220+220)" / 3 / =D45/D43 | E55: 120 (mOhm) / 5 / =IF(ISNUMBER(F45),F45,D45)/D43 | F55: F45 is now a numeric selected value, following the IF(selected,selected,calculated) idiom used everywhere else in this workbook. 5 x 120 mOhm = 24.0 mOhm, which is below D38 and matches the SMath design sheet. Note the old network was NOT three equal resistors: it was five 220 mOhm parts (three single + two in series, equivalent to 3.5 in parallel) sharing power 28.6 / 28.6 / 28.6 / 7.1 / 7.1 %, so the "N identical resistors" model behind D46 never described it.
B56: Device Setting | C56: F61 | D56: 78 (kOhm) | E56: 30 (kOhm) | F56: Consequence of the R.CS correction, not an independent change: D61 R.BM.max = 16.7*(P.in.BM*R.CS) is proportional to R.CS, so it fell from 78.7 to 30.1 kOhm. Leaving 78 kOhm would have moved the burst entry to 195 W. 30 kOhm reproduces the D57 = 75 W that was already selected. NOTE: D57 = 75 W is itself a leftover from the 240 W example - it is 11 % of P.in here, not the 30 % it was there.
B57: Device Setting | C57: D45 / B45 | D57: =D44 (122.668 mOhm) | E57: =LOOKUP(D44/10^INT(LOG10(D44)),{E24 mantissas})*10^INT(LOG10(D44)) | F57: D44 is the ceiling, not a part number - 122.668 mOhm cannot be bought. D45 now reports the largest E24 value at or below it (120 mOhm), so the row reads as a suggestion and F45 stays the place where the real choice goes. D46 already takes IF(ISNUMBER(F45),F45,D45)/D43, so leaving F45 empty falls back on the suggestion.
B58: BOM&Schematics | C58: C19:G22 | D58: the capacitor bank was one row holding only the SINGLE value (680 uF), with the count on its own line and no total anywhere; a first fix put Count/TOTAL in H/I, which sits under the Power Part Schematics picture and overwrote the column G source hint | E58: four rows inside the existing C..F table: single, count, TOTAL (= E19*E20/1000, in mF) and the ceramic. The blank row 22 is used so no row is inserted and nothing below moves | F58: A bank is only defined by single x count = total. Column G carries =IF(E..,"","<source sheet>") on every row of this sheet and must not be taken.
B59: BOM&Schematics | C59: F44 / F38 | D59: C.f unit "uF"; number of sense resistors unit "mOhm" | E59: C.f unit "nF"; count unit "-" | F59: Labelling errors. C.f is 200 nF everywhere else (CompensationNet&Check F94) and D38 is a count.
B60: CompensationNet&Check | C60: F43 | D60: 16 kOhm - BELOW its own D43 minimum of 16.024 kOhm | E60: 16.5 kOhm | F60: Outside the D42..D43 window the FB anti-saturation circuit loses its linear range. 16.5 k sits inside 16.02..18.22 k with 3 % margin at the bottom and 10 % at the top.
B61: Device Setting | C61: F108 | D61: 32 kOhm - V.BO = 90.5 V, ABOVE V.AC_min = 90 V | E61: 30 kOhm - V.BO = 84.9 V | F61: D108 gives 31.82 k as the ceiling for a 90 V brown-out point. At 32 k the converter browns out at minimum line. 30 k also keeps CFG inside the 15..47 k morphing window.
B62: Res. Tank Design / Power Components | C62: C65 C67 C60 C61 C84 C85 / F60 F61 F84 F85 / D78 D100 | D62: CC!C25/C26/C29/C30 (a SINGLE point, theta=pi/4) were labelled "mains cycle" rms, and those values fed the semiconductor loss calculations directly. | E62: Relabelled "@theta=pi/4 (approx.)", and added yellow input cells in column F carrying the line-cycle rms from the SMath sheet (F60 10.90 / F61 7.707 / F84 and F85 28.31 A). The loss formulas D78 and D100 prefer the selected value via IF(ISNUMBER(F..),F..,D..). | F62: theta=pi/4 equals the line-cycle rms only if the envelope is sin(theta). The real envelope is sin^2(theta), so the primary is understated by 5.9 % and the secondary by 17.6 %; loss goes as the square, so rectifier loss is out by a factor 1.38 (7.93 -> 10.98 W, required Rth 12.60 -> 9.11 C/W). The CC sheet had only three theta columns, too few to integrate, so the SMath figures were imported. HISTORY.md C.18
B63: CompensationNet&Check | C63: H132:AV167 (196 cells) | D63: The high-frequency pole f_px is computed in D104 and then referenced by no loop-verification formula at all. Gain, phase and crossover were built from f_z and f_p alone. | E63: Inserted the f_px term into 196 cells: /(1+(f/f_px)^2) into the 120 gain formulas, -ATAN(f/f_px) into the 76 phase formulas. | F63: Phase near crossover came out 0.8 to 1.1 degrees optimistic. In a design whose margin sits close to 45 degrees that can invert the verdict. Appendix C.12
... B75: Design Spec | C75: C15 · C59 | D75: Two different inputs are both labelled "Config.". D15 selects the input arrangement and feeds only D80; D59 selects the output rectifier configuration and drives 125 cells through D107. | E75: C15 = "Config.mains", C59 = "Config.rect" | F75: Going by the name, a user edits the upper one, changes nothing about the rectifier configuration, and believes they did. The wiring is correct, so only the labels were fixed.
B76: Res. Tank Design | C76: D28 · D29 · D30 | D76: The ZVS check is never recomputed after the tank is selected. D28 re-derives f.n = 0.82111 from the fitted expression [36] (whose exponent 5 has no basis in any ST document); D29 takes the phase at the design ceiling Q_ZVS = 0.8466 rather than the Q the converter runs at; and D30 divides by the TARGET 'Design Spec'!D102 = 150 kHz rather than the real resonant frequency. Result: T_ZC = 303 ns, 34 % below the truth. | E76: The realised values were already inside the workbook - the grid solution RTC!$BB$149 = 0.84006 and RTC!$C$41 = 0.7717. D28 -> RTC!$BB$149, both Q occurrences in D29 -> RTC!$C$41, and the denominator of D30 -> D55 (the real f.r, 151.748 kHz). T_ZC 303 -> 457 ns. The tank-selection path (D26 -> D27 -> D43..D45) was not touched.
B77: CompensationNet&Check | C77: D110 | D77: The verification block carries its own line-frequency input, D110 = 50 Hz, while the design block designs at the worst case of 47 Hz (D7, D68, D73, D83). The design is therefore verified at a gentler line frequency than it was designed for, and D116, AV122, D125, D126, D128 and D129 all come out optimistic. | E77: D110 = 47 (the worst case of the 47-63 Hz specification, matching Design Spec!D17). Third harmonic 3.86 -> 4.31 %, burst FB ripple 47.3 -> 52.9 mV, R_BM adjustment range 2.37 -> 2.65 kohm.
B78: Power Components | C78: D22 · D33 | D78: Hold-up is assumed to start discharging from the nominal output, 25 V (D14). The real output swings 24.41 to 25.59 V on the 2f_L ripple and the AC can be lost at any phase, so the worst case is the ripple trough. Energy goes as V^2, so the result is 12.5 % optimistic. The actual ripple is already in D31, one row below. | E78: D14^2 replaced by (D14-D31/2)^2 in both formulas. Required capacitance 59.77 -> 67.22 mF, achieved hold-up 15.10 -> 13.42 ms. The chain is D22 -> D31 -> D26 -> D23/D24 (selected by hand), so this is not a circular reference.
...

Sheet Design Spec
I8: Release 1.0
B10: Input data specs. and pre design choices
B12: Parameters | C12: Name | D12: Value | E12: Unit
B13: Minimum Input voltage | C13: VAC.min | D13: 90 | E13: Vac
B14: Maximum Input voltage | C14: VAC.max | D14: 264 | E14: Vac
B15: =IF(D13>(190/SQRT(2)),"Select high mains configuration (1 = FB, 2 = HB)",IF(AND(D13<=(190/SQRT(2)),D14*SQRT(2)>245),"Selected configuration: universal mains range","Select low mains configuration (1 = FB, 2 = HB)")) -> Selected configuration: universal mains range | C15: Config.mains | D15: 1 | E15: ="-" -> -
B16: Line frequency | C16: fl | D16: 50 | E16: Hz
B17: Minimum Line frequency | C17: fl.min | D17: 47 | E17: Hz
B19: Parameters | C19: Name | D19: Value | E19: Unit | F19: Selected value
B20: Minimum voltage for Res. Tank Design | C20: Vin.min | D20: =MIN(2*D13,245/SQRT(2)) -> 173.24116 | E20: Vac | F20: =D20 -> 173.24116
B22: Parameters | C22: Name | D22: Value | E22: Unit | J22: *25
B23: Regulated Output Voltage - TARGET (the divider is chosen to hit this) | C23: V.out | D23: 25 | E23: V | F23: realised value (selected divider) -> | G23: ='CompensationNet&Check'!D38 -> 25.176818
B24: Minimum admitted voltage (for hold up req) | C24: Vo_min_adm | D24: 19 | E24: V
B25: Output voltage ripple pk-pk | C25: ∆vout | D25: 5 | E25: %
B26: Hold up capability | C26: Thold | D26: 12 | E26: ms
B27: Maximum Output Power | C27: Pout | D27: 657.5 | E27: W
B28: Expected HB efficiency | C28: ηLLC | D28: 98 | E28: %
B29: Max capacitor height (empty or 0 for unlimited) | C29: h | D29: 25 | E29: mm
B31: Output cap estimation (MCLPR series) | C31: Name | D31: Value | E31: Unit
B32: Output capacitor working voltage | C32: W.V | D32: =OutCap_Sel_DB!V4 -> 50 | E32: V | F32: =IF(D32="","No solution found, increase max height","")
B33: Single capacitor value | C33: Cout.s.est | D33: =OutCap_Sel_DB!W4 -> 4700 | E33: uF
B34: Equivalent Series Resistor | C34: ESR.single | D34: =OutCap_Sel_DB!Z4 -> 0.084656885 | E34: Ω
B35: Case Size diameter | C35: ØD | D35: =OutCap_Sel_DB!X4 -> 30 | E35: mm
B36: Case Size height | C36: h | D36: =OutCap_Sel_DB!Y4 -> 25 | E36: mm
B37: Estimated number of cap | C37: n.Cap | D37: =OutCap_Sel_DB!AA4 -> 16 | E37: -
B38: Expected ouptut cap volume [cm3] | C38: Cap.Volume | D38: =OutCap_Sel_DB!U4 -> 282.74334 | E38: cm3
B40: Parameters | C40: Name | D40: Value | E40: Unit
B41: Upper Resonant Frequency | C41: f.R1 | D41: 150 | E41: kHz
B42: Minimum switching frequency | C42: fsw.min | D42: 50 | E42: kHz
B43: Maximum Switching Frequency (1.5*f.R1 sugg) | C43: fsw.max | D43: =1.5*D41 -> 225 | E43: kHz
B45: Parameters | C45: Name | D45: Value | E45: Unit
B46: Single HB midpoint estimated Cap | C46: c.HB | D46: 800 | E46: pF
B47: Dead Time | C47: t.D | D47: 220 | E47: ns
B48: Parassitic Capacitance | C48: Cp | D48: 2 | E48: nF
B49: EMI filter resistance | C49: R.EMI | D49: 0.15 | E49: Ω
B51: Parameters | C51: Name | D51: Value | E51: Unit
B52: Bridge Rectifier Voltage Drop | C52: Vf.BR | D52: 0.08 | E52: V
B53: Dynamic Resistance (1 diode) | C53: Rd | D53: 0.04 | E53: Ω
B55: Output stage configuration (CT/FB)
B57: Parameters | C57: Name | D57: Value | E57: Unit
...

Sheet Preliminary Calculation
B4: Preliminary Calculations
B6: Parameters | C6: Name | D6: Value | E6: Unit
B7: Output current | C7: Iout | D7: ='Design Spec'!D98/'Design Spec'!D95 -> 26.3 | E7: A
B8: Output rectifier efficiency | C8: η.rect | D8: ='Design Spec'!D95/('Design Spec'!D95+'Design Spec'!D106*'Design Spec'!D107)*100 -> 100 | E8: %
B9: Transformer output power | C9: P.sec | D9: ='Design Spec'!D98/'Preliminary Calculation'!D8*100 -> 657.5 | E9: W
B10: LLC converter input power | C10: P.in.LLC | D10: ='Design Spec'!D98/('Preliminary Calculation'!D8/100*'Design Spec'!D99/100) -> 670.91837 | E10: W
B11: Max mains input rms current | C11: I.in.max | D11: =D10/'Design Spec'!D78 -> 7.4546485 | E11: A
B12: Output rectifier dissipation | C12: P.d.Drect | D12: =('Design Spec'!D98)*((1-'Preliminary Calculation'!D8/100)/('Preliminary Calculation'!D8/100)) -> 0 | E12: W
B13: LLC converter dissipation (trafo+MOS) | C13: P.d.LLC | D13: =(D9)*((1-('Design Spec'!D99/100))/('Design Spec'!D99/100)) -> 13.418367 | E13: W
B14: Bridge rectifier dissipation | C14: P.D.br | D14: =2*((D11*SQRT(2))*2/PI()*'Design Spec'!D108)+2*('Design Spec'!D109*(D11^2)) -> 5.5195894 | E14: W
B15: EMI filter resistance dissipation | C15: P.D.Rin | D15: ='Design Spec'!D114*D11^2 -> 8.3357677 | E15: W
B16: TOTAL power dissipation | C16: P.D | D16: =D15+D14+D13+D12 -> 27.273724 | E16: W
B17: HB converter expected efficiency | C17: η.HB | D17: =D9/(D9+D13)*100 -> 98 | E17: %
B18: EMI filter and bridge rectifier efficiency | C18: η.ac | D18: =D10/(D10+(D15+D14))*100 -> 97.976652 | E18: %
B19: Total expected efficiency | C19: η.tot | D19: =D17*D8/100*D18/100 -> 96.017119 | E19: %
B20: Rated input power | C20: P.in | D20: ='Design Spec'!D98/D19*100 -> 684.77372 | E20: W

Sheet Res. Tank Design
B4: Resonant Tank Design
B6: FHA-based design
B8: Parameters | C8: Name | D8: Value | E8: Unit | F8: Selected Value
B9: Physical Turn Ratio (npri/nsec): | C9: n | D9: =(SQRT(2)*'Design Spec'!D89)/(2*('Design Spec'!D95+'Design Spec'!D107*'Design Spec'!D106)) -> 6.045763 | E9: ="-" -> - | F9: 6.0241
B10: Maximum Voltage Gain@Vin.min | C10: M.Vmin.pk | D10: =2*IF(F9,F9,D9)*(('Design Spec'!D95+'Design Spec'!D107*'Design Spec'!D106))/(SQRT(2)*'Design Spec'!D83) -> 1.2294082 | E10: ="-" -> -
B11: Minimum Voltage Gain@Vin.min | C11: M.Vmax.pk | D11: =2*IF(F9,F9,D9)*(('Design Spec'!D95+'Design Spec'!D107*'Design Spec'!D106))/(SQRT(2)*'Design Spec'!D79) -> 0.80675795 | E11: ="-" -> -
B12: Min λ ratio for min gain req | C12: λ.min.1 | D12: =1/(2*IF(F9,F9,D9)*(('Design Spec'!D95+'Design Spec'!D107*'Design Spec'!D106))/(SQRT(2)*'Design Spec'!D81))-1 -> 0.56039906 | E12: ="-" -> -
B13: Min λ ratio for max freq req | C13: λ.min.2 | D13: =D12/(1-('Design Spec'!D102/'Design Spec'!D104)^2) -> 1.0087183 | E13: ="-" -> -
B14: Min λ ratio for max freq req (TD) | C14: λ.min.TD | D14: =D12/(1-(((PI()^2)/8)*('Design Spec'!D102/'Design Spec'!D104)^2)) -> 1.2406756 | E14: ="-" -> -
B15: Min λ ratio for min freq req | C15: λ.min.3 | D15: =(('Design Spec'!$D$103/'Design Spec'!$D$102)^2)/(1-('Design Spec'!$D$103/'Design Spec'!$D$102)^2) -> 0.125 | E15: -
B16: Maximum value | C16: λ | D16: =MAX(D12,D13,D14,D15) -> 1.2406756 | E16: ="-" -> - | F16: removed 1.2 factor on λ.min.1
B17: Equivalent output impedance | C17: Rac | D17: =((IF(F9,F9,D9))^2)*(4/((PI())^2))*(((('Design Spec'!D95+'Design Spec'!D107*'Design Spec'!D106))^2)/('Preliminary Calculation'!D10)) -> 13.701084 | E17: Ω
B18: For ZVS at Vin.min and max load | C18: QZVS.1 | D18: =IF(D10>1,(D16/D10)*SQRT((1/D16)+((D10^2)/((D10^2)-1))),NA()) -> 1.957171 | E18: ="-" -> -
B19: For ZVS at Vin.max and zero load | C19: QZVS.2 | D19: =(2/PI())*(D16)*(('Design Spec'!D112*(10^-9))/(D17*'Design Spec'!D111*(10^-12))) -> 15.85317 | E19: ="-" -> -
B20: For ZVS at Vin.max and zero load | C20: QZVS.3 | D20: =((SQRT((D16*(1+D16))))/(2*IF(F9,F9,D9)))*((SQRT(2)*'Design Spec'!D83)/((('Design Spec'!D95+'Design Spec'!D107*'Design Spec'!D106)))) -> 1.3561962 | E20: ="-" -> - | F20: Not used since evaluated at f.o
B22: ZVS condition
B24: Parameters | C24: Name | D24: Value | E24: Unit
B25: Margin to achieve ZVS | C25: ZVSmargin | D25: 15 | E25: %
B26: Selected quality factor | C26: QZVS | D26: =1/(1+(D25/100))*MIN(D18:D19) -> 1.7018878 | E26: ="-" -> -
B27: Resonant tank characteristic imp | C27: Z0 | D27: =D17*D26 -> 23.317707 | E27: Ω
B28: Minimum fsw.norm at Vin.min.pk | C28: f.n.min | D28: =RTC!$BB$149 -> 0.83781782 | E28: ="-" -> -
B29: Minimum resonant tank phase shift | C29: φ.min | D29: =ATAN(((((D50^2)+(D50)+(((D28^2)-1)*(RTC!$C$41^2)))*(D28^2))-(D50^2))/(RTC!$C$41*(D28)^3)) -> 0.36747527 | E29: ="-" -> -
B30: Resonant current ZC instant | C30: T.ZC | D30: =(D29)/(2*PI()*D28*D55)*1000000 -> 460.01805 | E30: ns
B31: Reference Dead time | C31: T.D | D31: ='Design Spec'!D112 -> 220 | E31: ns
B32: ZVS condition satisfied? | C32: =IF(D30>D31,"Yes","No, increase ZVS margin") -> Yes
B34: Parameters | C34: Name | D34: Value | E34: Unit
B35: Peak Resonant Current | C35: IR1.pk | D35: =(2*PI()*'Design Spec'!D98)/(SQRT(2)*('Preliminary Calculation'!D17/100)*'Design Spec'!D83*COS('Res. Tank Design'!D29)) -> 18.437047 | E35: A
B36: Minimum current for achieving ZVS | C36: IR0 | D36: =D35*SIN(D29) -> 6.6237009 | E36: A
B37: Transition time | C37: T.T | D37: ='Design Spec'!D111*(10^-12)*(SQRT(2)*'Design Spec'!D83/'Res. Tank Design'!D36)*10^9 -> 29.590708 | E37: ns
B39: Resonant Tank Parameters
B41: Parameters | C41: Name | D41: Value | E41: Unit | F41: Selected Value
B42: Turn Ratio | C42: n | D42: =IF(F9,F9,D9) -> 6.0241 | E42: ="-" -> -
B43: Resonant Capacitor | C43: C.r | D43: =1/(2*PI()*'Design Spec'!D102*'Res. Tank Design'!D27)*1000000 -> 45.503314 | E43: nF | F43: 100
B44: Leakage inductance | C44: L.r | D44: =1/(IF(F43,F43,D43)*(10^-12)*(2*PI()*'Design Spec'!D102*1000)^2)*1000 -> 11.257909 | E44: µH | F44: 11
B45: Magnetizing inductance | C45: L.m | D45: =IF(F44,F44,D44)/D16 -> 8.8661374 | E45: µH | F45: 20
B47: Final Design Check
B49: Parameters | C49: Name | D49: Value | E49: Unit
B50: Series over parallel inductance ratio | C50: λ | D50: =IF(F44,F44,D44)/IF(F45,F45,D45) -> 0.55 | E50: ="-" -> -
B51: Real Turn Ratio | C51: n.T | D51: =IF(F9,F9,D9)*(1+D50)^0.5 -> 7.499944 | E51: ="-" -> -
B52: Series resonant characteristic imp | C52: Z.o | D52: =(IF(F44,F44,D44)/IF(F43,F43,D43)*1000)^0.5 -> 10.488088 | E52: Ω
...

Sheet Power Components
B4: Input capacitor selection
B6: Parameters | C6: Name | D6: Value | E6: Unit | F6: Selected Value
B7: Minimum Input Cap. | C7: C.in.min | D7: =3*'Preliminary Calculation'!D20 -> 2054.3212 | E7: nF | F7: 2200
B9: Output capacitor selection
B11: Parameter | C11: Name | D11: Value | E11: Unit
B12: Output Power | C12: Pout | D12: ='Design Spec'!D27 -> 657.5 | E12: W
B13: Output current | C13: Iout | D13: ='Preliminary Calculation'!D7 -> 26.3 | E13: A
B14: Regulated output voltage | C14: Vout | D14: ='Design Spec'!D23 -> 25 | E14: V
B15: Minimum admitted voltage | C15: Vo_min_adm | D15: ='Design Spec'!D24 -> 19 | E15: V
B16: Output voltage ripple | C16: Ripple | D16: ='Design Spec'!D25 -> 5 | E16: %
B17: Hold up capability | C17: Thold | D17: ='Design Spec'!D26 -> 12 | E17: ms
B18: Minimum Mains frequency | C18: fl | D18: ='Design Spec'!D17 -> 47 | E18: Hz
B20: Parameter | C20: Name | D20: Value | E20: Unit
B21: Output cap considering ripple pk-pk | C21: Cout1 | D21: =D13/(2*PI()*D18*D14*(D16/100))*10^6 -> 71247.234 | E21: uF
B22: Ouptut cap considering hold up | C22: Cout2 | D22: =(2*D12*D17*(10^-3))/(((D14-D31/2)^2)-(D15^2))*10^6 -> 67222.382 | E22: uF
B23: Number of output capacitors | C23: n.Cout | D23: 160 | E23: -
B24: Insert the single capacitor value | C24: Cout.single | D24: 470 | E24: uF
B25: Insert the ESR value of the single capacitor | C25: ESR.single | D25: 30 | E25: mΩ
B26: Total ouptut capacitor Cout | C26: Cout | D26: =D24*D23 -> 75200 | E26: uF
B27: Total ESR of Cout | C27: ESR | D27: =D25/D23 -> 0.1875 | E27: mΩ
B28: Output cap RMS current | C28: I.Cout.RMS | D28: =CC!J31 -> 30.222321 | E28: A
B30: Parameter | C30: Name | D30: Value | E30: Unit
B31: Low frequency ripple voltage pk-pk recalculation | C31: V_Ripple_pk-pk | D31: =D13/(2*PI()*D18*D26*(10^-6)) -> 1.1842958 | E31: V
B32: % Ripple pk-pk on Vout | C32: Ripple pk-pk % | D32: =D31/D14*100 -> 4.7371831 | E32: %
B33: Hold up time recalculation | C33: Thold | D33: =D26/(2*D12)*(((D14-D31/2)^2)-(D15^2))/1000 -> 13.4241 | E33: ms
B34: Estimated maximum R&N @ Vinmin | C34: R&N_0 | D34: =D27*CC!$E$24 -> 18.490868 | E34: mV
B35: Maximum allowed R&N @ fsw | C35: R&N_max | D35: 30 | E35: mV
B36: Displacement factor of ceramic capacitor | C36: DF | D36: 2.5 | E36: %
B37: Suggested minimum ceramic capacitor | C37: Cceramic min | D37: =IF((1-D35/D34)*(D36/100)*(10^6)/(D27*2*PI()*CC!$E$21*D35/D34)>0,(1-D35/D34)*(D36/100)*(10^6)/(D27*2*PI()*CC!$E$21*D35/D34),0) -> 0 | E37: uF
B38: Select the ceramic capacitor | C38: Cceramic | D38: 10 | E38: uF
B39: Estimated R&N @ fsw | C39: R&N | D39: =D34/(D27*10^(-6)*2*PI()*CC!$E$21*D38/(D36/100)+1) -> 17.445662 | E39: mV
B40: Estimated dissipated power on output capacitors | C40: P.Cout | D40: =D28*D28*(((2*PI()*CC!E21*1000*D38*10^-6)/(D36/100))+(D27/1000)^-1)^-1 -> 0.16157979 | E40: W
B42: Input Bridge Rectifier
B44: Parameter | C44: Name | D44: Value | E44: Unit
B45: Maximum RMS Input Current | C45: Iin | D45: ='Preliminary Calculation'!D11 -> 7.4546485 | E45: A
B46: Parameter | C46: Name | D46: Value | E46: Unit
B47: Selected Bridge Forward Voltage (1 diode) | C47: Vth | D47: ='Design Spec'!D52 -> 0.08 | E47: V
B48: Dynamic Resistance (1 diode) | C48: Rd | D48: ='Design Spec'!D53 -> 0.04 | E48: Ω | G48: Bridge rectifier schematic
G49: =C50 -> GBJ1506U
B50: Please Select a BRIDGE RECTIFIER part number | C50: GBJ1506U
...

Sheet Device Setting
B1: Minimum switching frequency = lower resonant frequency | C1: f.sw.min | D1: ='Res. Tank Design'!D56 -> 90.393933 | E1: kHz
B2: Maximum switching frequency at Vinmax and max load | C2: f.sw.max | D2: =RTC!$BD$212 -> 249.02959 | E2: kHz
B3: Maximum switching frequency for component design | C3: f.sw.max.design | D3: =MAX(D2,MIN('Design Spec'!D104,D2*1.5)) -> 249.02959 | E3: kHz
B4: Resonant Frequency | C4: f.r | D4: ='Res. Tank Design'!D55 -> 151.74828 | E4: kHz
B10: 1-VCO timing components setting
B12: DS_Reference voltage for CT Typ. | C12: VREF | D12: 1.5 | E12: V
B13: DS_Oscillator idle time 350ns Typ. | C13: Tidle | D13: 250 | E13: ns
B14: DS_Timing resistor operating range [5-30]kΩ | C14: Rtmax | D14: 30 | E14: kΩ
B15: DS_IEA_max typ. 400uA | C15: I.CTL.max | D15: 0.4 | E15: mA
B16: DS_Extra osccillator current at start-up: | C16: IOSC.SU | D16: 0.412 | E16: mA
B18: Parameters | C18: Name | D18: Value | E18: Unit | I18: VCO block diagram
B19: Maximum Timing Capacitor | C19: CT.max | D19: =(D15*(10^-3))*((2*D13*D3*(10^-6))-1)*((2*D13*D1*((10^-6)))-1)/(2*D12*((D3-D1)*10^3))*10^12 -> 702.5877 | E19: pF
B20: Minimum Timing Capacitor | C20: CT.min | D20: =(1/(D14*(10^3)))*((1/(2*D1*10^3))-(D13*(10^-9)))*10^12 -> 176.04482 | E20: pF
B21: Select the timing capacitor between CTmin and Ctmax | C21: CT | D21: 470 | E21: pF | F21: 470
C22: k.CT (>1) | D22: =MIN(D19/D21,D21/D20) -> 1.4948674 | E22: -
B23: Parameters | C23: Name | D23: Value | E23: Unit | F23: Selected Value
B24: Minimum Resistor value | C24: RT.ceil (NOT a minimum) | D24: =(1/(D21*(10^-12)))*(1/(2*D1*(10^3))-(D13*10^-9))/1000 -> 11.236904 | E24: kΩ | F24: 11
C25: k.RT.ceil (>1) | D25: =D24/IF(ISNUMBER(F24),F24,D24) -> 1.0215367 | E25: -
B26: Parameters | C26: Name | D26: Value | E26: Unit
B27: Actual Max. switching frequency | C27: f.Max | D27: =1/(2*(((D21*(10^-12))/(((D15*(10^-3))/D12)+(1/(F24*(10^3)))))+(D13*(10^-9))))/1000 -> 319.60997 | E27: kHz
B28: Actual Min. switching frequency | C28: f.Min | D28: =1/(2*(D21*F24*(10^-9)+D13*(10^-9)))/1000 -> 92.250923 | E28: kHz
B29: Actual Start-up switching frequency | C29: f.start-up | D29: =1/(2*(((D21*(10^-12))/((((D15+D16)*(10^-3))/(D12))+(1/(F24*(10^3)))))+(D13*(10^-9))))/1000 -> 503.32915 | E29: kHz
C31: P.in | D31: ='Preliminary Calculation'!D20 -> 684.77372 | E31: W
B32: Composite resonant peak = load + magnetizing (NOT I.trafo.pk alone) [79] | C32: Ilr.pk.max | D32: =IF(2*CC!E28/(PI()*CC!E27)>=1,CC!E28,CC!E28*(2*ACOS(-2*CC!E28/(PI()*CC!E27))/PI()-1)+CC!E27*SQRT(1-(2*CC!E28/(PI()*CC!E27))^2)) -> 18.315444 | E32: A
B33: Maximum rms current on sense resistor (at Vinmin) | C33: I.Rcs.rms.max | D33: =MAX(CC!E29,'Preliminary Calculation'!D11) -> 13.760292 | E33: A
B35: 2-ISEN (Pin6) Current sense resistor calculation
B37: Parameters | C37: Name | D37: Value | E37: Unit
B38: Max input power at FB voltage clamped to the VFB.max | C38: R.CS.max1 | D38: =16.8/D31*1000 -> 24.533652 | E38: mΩ
B39: Minimum input voltage, the maximum input peak current | C39: R.CS.max2 | D39: =0.55/D32*1000 -> 30.029302 | E39: mΩ
B40: Sense dissipation @ low mains | C40: P.Rcs.avg | D40: =(MIN(D38,D39)/1000)*(D33)^2 -> 4.6453396 | E40: W
B41: Single sense resistor maximum power dissipation | C41: P.Rcs.sing | D41: 1 | E41: W
B42: Minimum number or parallel sense resistors | C42: N.Rcs.sing | D42: =_xlfn.CEILING.MATH(D40/D41) -> 5 | E42: -
B43: Select number of parallel sense resistors | C43: N.Rcs.parall | D43: 5 | E43: -
B44: Maximum value of single sense resistor | C44: Max.Rcs.parall | D44: =MIN(D38,D39)*D43 -> 122.66826 | E44: mΩ
B45: Suggested single sense resistor (largest E24 value at or below D44) - put your actual choice in F45 | C45: R.CS.single | D45: =LOOKUP(D44/10^INT(LOG10(D44)),{1,1.1,1.2,1.3,1.5,1.6,1.8,2,2.2,2.4,2.7,3,3.3,3.6,3.9,4.3,4.7,5.1,5.6,6.2,6.8,7.5,8.2,9.1})*10^INT(LOG10(D44)) -> 120 | E45: mΩ | F45: 120 | I45: =D43*((180^-1+180^-1+240^-1)^-1) -> 327.27273 | J45: 180||180||240
B46: Current sense resistor | C46: R.CS | D46: =IF(ISNUMBER(F45),F45,D45)/D43 -> 24 | E46: mΩ
B47: Actual estimated power dissipation on current sense resistor | C47: P.Rcs.act | D47: =(D46/1000)*(D33)^2 -> 4.544295 | E47: W
B48: Actual estimated maximum input power | C48: Pin.max | D48: =16.8/D46*1000 -> 700 | E48: W
B49: OCP1 / OCP2 trip currents [84] - ADDED | C49: I.OCP1 | D49: =0.55/D46*1000 -> 22.916667 | E49: A | F49: I.OCP2 | G49: =0.75/D46*1000 -> 31.25 | H49: A
B50: OCP1 margin over the composite peak D32 - target > 1.2 | C50: k.OCP1 | D50: =D49/D32 -> 1.2512209 | E50: -
...

Sheet CompensationNet&Check
B2: Link input data | C2: Vinmax | D2: ='Design Spec'!D79 -> 264
B3: Link input data | C3: Vinmin | D3: ='Design Spec'!D83 -> 173.24116
B4: Link input data | C4: Vout | D4: ='Design Spec'!D95 -> 25 | E4: V
B5: Link_power components | C5: Cout | D5: ='Power Components'!D26*10^-6 -> 0.0752 | E5: F
B6: Link input data | C6: fl | D6: ='Design Spec'!D90 -> 50 | E6: Hz
B7: Link input data | C7: flmin | D7: ='Design Spec'!D91 -> 47 | E7: Hz
B11: FB and secondary side voltage control loop
B13: Parameters | C13: Name | D13: Value | E13: Unit | H13: Secondary side voltage control loop schematics:
B14: Feedback supply voltage | C14: V.Z | D14: 12 | E14: V
B15: Max feedback current | C15: I.FB.max | D15: 300 | E15: µA
B16: Current out of FB pin | C16: I.FB.steady | D16: 150 | E16: µA
B17: FB pin internal resistance | C17: R.FB | D17: 35 | E17: kΩ
B19: Please Select a Voltage Regulator part number | C19: TL431AIT
B21: Parameters | C21: Name | D21: Value | E21: Unit
B22: Tx431 referemce voltage | C22: V.R | D22: 2.495 | E22: V
B23: Tx431 min operating current | C23: I.min | D23: 0.8 | E23: mA
B25: Please Select an Optocoupler part number | C25: SFH617A
B27: Parameters | C27: Name | D27: Value | E27: Unit
B28: Optodiode voltage drop | C28: V.Fo | D28: 1.15 | E28: V
B29: Optocoupler transfer ratio when Itr = 150uA | C29: CTR.steady | D29: 0.37
B30: Optocoupler capacitance | C30: C.opto | D30: 3 | E30: nF
B31: Optocoupler transfer ratio when Itr = 300uA | C31: CTR.max | D31: 0.53 | E31: ="-" -> -
B33: Output feedback divider and Vout setting
B35: Parameters | C35: Name | D35: Value | E35: Unit | F35: Selected value
B36: Upper resistor divider | C36: R.I | D36: 100 | E36: kΩ
B37: Lower resistor divider | C37: Ro | D37: =D22/(D4-D22)*D36 -> 11.086425 | E37: kΩ | F37: 11
B38: Regulated output voltage - ACTUAL, from the selected divider (target is Design Spec D23) | C38: Vout | D38: =D22*(D36+F37)/F37 -> 25.176818 | E38: V
B40: Parameters | C40: Name | D40: Value | E40: Unit | F40: Selected value
B41: Limiting Resistor | C41: R.p.Max | D41: =D28/D23 -> 1.4375 | E41: kΩ | F41: 1.3
B42: External EA biasing resistor_max value | C42: R.B.max | D42: =(D14-(D22+D28))/(((D16*10^-6)/D29)+(D28/(F41*1000)))/1000 -> 6.4766398 | E42: kΩ
B43: External EA biasing resistor_min value | C43: R.B.min | D43: =(D14-(D22+D28))/(((D15*10^-6)/D31)+(D28/(F41*1000)))/1000 -> 5.7594747 | E43: kΩ | F43: 6.2
B44: Maximum Feedback current | C44: I.FB | D44: =((D14-(D22+D28))/(F43*1000)-(D23*10^-3))*D31*(10^6) -> 290.21774 | E44: µA
B46: DS_Gain | C46: K.HV | D46: =3.34*(10^-3) -> 0.00334 | E46: ="-" -> -
B47: DS_Gain | C47: K.M | D47: 0.2 | E47: 1/V^2
B48: DS_Gain | C48: K.FF | D48: 0.2 | E48: V^3
B49: DS_Offset | C49: Vos | D49: 0.5 | E49: V
B51: Link to Preliminary calculations | C51: η.HB | D51: ='Preliminary Calculation'!D17/100 -> 0.98
B52: Link to Device Setting | C52: R.CS | D52: ='Device Setting'!D46*10^(-3) -> 0.024 | E52: Ω
B56: Feedback Loop Requirements
B58: Parameters | C58: Name | D58: Value | E58: Unit
...

Sheet BOM&Schematics
I3: Power Part Schematics
C4: BOM and Schematics
C6: Resonant tank parameters
C8: Parameters | D8: Name | E8: Value | F8: Unit | G8: {=IF(AND(VALUE(E9:E13)),"","Please compile on sheet")}
C9: Magnetizing inductance | D9: L.m | E9: ='Res. Tank Design'!F45 -> 20 | F9: µH | G9: =IF(E9,"","Res. Tank Design")
C10: Leakage inductance | D10: L.r | E10: ='Res. Tank Design'!F44 -> 11 | F10: µH | G10: =IF(E10,"","Res. Tank Design")
C11: Resonant Capacitor | D11: C.r | E11: ='Res. Tank Design'!F43 -> 100 | F11: nF | G11: =IF(E11,"","Res. Tank Design")
C12: Pri. to Sec. turn ratio | D12: n | E12: ='Res. Tank Design'!F9 -> 6.0241 | F12: ="-" -> - | G12: =IF(E12,"","Res. Tank Design")
C13: Auxiliary to Secondary turn ratio | D13: n.aux_sec | E13: ='Device Setting'!$F$83 -> 1.5 | F13: ="-" -> - | G13: =IF(E13,"","Device Setting")
C15: Input and output cap
C17: Parameters | D17: Name | E17: Value | F17: Unit | G17: {=IF(AND(VALUE(E18:E21)),"","Please compile on sheet")}
C18: PFC input Capacitor | D18: Cin | E18: ='Power Components'!$F$7 -> 2200 | F18: nF | G18: =IF(E18,"","Power Components")
C19: Output EL capacitor (single) | D19: C.out.single | E19: ='Power Components'!$D$24 -> 470 | F19: µF | G19: =IF(E19,"","Power Components")
C20: Number of output EL capacitors | D20: n.Cout | E20: ='Power Components'!$D$23 -> 160 | F20: - | G20: =IF(E20,"","Power Components")
C21: Output capacitance TOTAL | D21: C.out | E21: =E19*E20/1000 -> 75.2 | F21: mF | G21: =IF(E21,"","Power Components")
C22: Output ceramic, high frequency | D22: Cout ceramic | E22: ='Power Components'!D38 -> 10 | F22: µF | G22: =IF(E22,"","Power Components")
C23: HVSU connecting diodes PN
C25: Selected component | D25: PN
C26: Example of Diodes PN (x 2) | D26: S1M
C28: Input Bridge Rectifier PN
C30: Selected component | D30: PN
C31: Input Bridge Rectifier PN | D31: ='Power Components'!$C$50 -> GBJ1506U | G31: =IF(ISBLANK(D31),"Power Components","")
C33: Sense resistor
C35: Parameters | D35: Name | E35: Value | F35: Unit | G35: {=IF(AND(VALUE(E36:E38)),"","Please compile on sheet")}
C36: Rsense total value | D36: ='Device Setting'!C$46 -> R.CS | E36: ='Device Setting'!$D$46 -> 24 | F36: mΩ | G36: =IF(E36,"","Device Setting")
C37: Single Rsense value | D37: ='Device Setting'!C$45 -> R.CS.single | E37: =IF('Device Setting'!F45,'Device Setting'!F45,'Device Setting'!D45) -> 120 | F37: mΩ | G37: =IF(E37,"","Device Setting")
C38: Number of Rsense | D38: ='Device Setting'!C$43 -> N.Rcs.parall | E38: ='Device Setting'!$D$43 -> 5 | F38: - | G38: =IF(E38,"","Device Setting")
C40: Compensation network and Output Divider
C42: Parameters | D42: Name | E42: Value | F42: Unit | G42: {=IF(AND(VALUE(E43:E50)),"","Please compile on sheet")}
C43: Feedback capacitor CFo | D43: C.fo | E43: =IF('CompensationNet&Check'!F93,'CompensationNet&Check'!F93,'CompensationNet&Check'!D93) -> 82 | F43: nF | G43: =IF(E43,"","CompensationNet&Checks")
C44: Feedback capacitor CF | D44: C.f | E44: =IF('CompensationNet&Check'!F94,'CompensationNet&Check'!F94,'CompensationNet&Check'!D94) -> 560 | F44: nF | G44: =IF(E44,"","CompensationNet&Checks")
C45: Feedback resistor RF | D45: R.f | E45: =IF('CompensationNet&Check'!F95,'CompensationNet&Check'!F95,'CompensationNet&Check'!D95) -> 47 | F45: kΩ | G45: =IF(E45,"","CompensationNet&Checks")
C46: feedback capacitor | D46: C.fx | E46: =IF('CompensationNet&Check'!F96,'CompensationNet&Check'!F96,'CompensationNet&Check'!D96) -> 1.55 | F46: nF | G46: =IF(E46,"","CompensationNet&Checks")
C47: Output Voltage upper resistor | D47: R.I | E47: ='CompensationNet&Check'!$D$36 -> 100 | F47: kΩ | G47: =IF(E47,"","CompensationNet&Checks")
C48: Output Voltage lower resistor | D48: R.o | E48: =IF('CompensationNet&Check'!$F$37,'CompensationNet&Check'!$F$37,'CompensationNet&Check'!$D$37) -> 11 | F48: kΩ | G48: =IF(E48,"","CompensationNet&Checks")
C49: Photodiode parallel resistor | D49: R.P | E49: =IF('CompensationNet&Check'!$F$41,'CompensationNet&Check'!$F$41,'CompensationNet&Check'!$D$41) -> 1.3 | F49: kΩ | G49: =IF(E49,"","CompensationNet&Checks")
C50: Bias resistor | D50: R.B | E50: =IF('CompensationNet&Check'!$F$43,'CompensationNet&Check'!$F$43,'CompensationNet&Check'!$D$43) -> 6.2 | F50: kΩ | G50: =IF(E50,"","CompensationNet&Checks") | I50: Controller Part Schematics
C52: L6790 pin configuration
C54: Parameters | D54: Name | E54: Value | F54: Unit | G54: {=IF(AND(VALUE(E55:E60)),"","Please compile on sheet")}
C55: Lower ZCD resistor (to GND) | D55: R.ZCD.L | E55: =IF('Device Setting'!F90,'Device Setting'!F90,'Device Setting'!D90) -> 19 | F55: kΩ | G55: =IF(E55,"","Device Setting")
...

Sheet RTC
C3: 1 | D3: 2 | E3: 3 | F3: 4 | G3: 5 | H3: 6 | I3: 7 | J3: 8 | K3: 9 | L3: 10 | M3: 11 | N3: 12 | O3: 13 | P3: 14 | Q3: 15 | R3: 16 | S3: 17 | T3: 18 | U3: 19 | V3: 20 | W3: 21 | X3: 22 | Y3: 23 | Z3: 24 | AA3: 25 | AB3: 26 | AC3: 27 | AD3: 28 | AE3: 29 | AF3: 30 | AG3: 31 | AH3: 32 | AI3: 33 | AJ3: 34 | AK3: 35 | AL3: 36 | AM3: 37 | AN3: 38 | AO3: 39 | AP3: 40 | AQ3: 41 | AR3: 42 | AS3: 43 | AT3: 44 | AU3: 45 | AV3: 46 | AW3: 47 | AX3: 48 | AY3: 49 | AZ3: 50 | BA3: 51 | BB3: 52 | BC3: 53 | BD3: 54 | BE3: 55 | BF3: 56 | BG3: 57 | BH3: 58 | BI3: 59 | BJ3: 60 | BK3: 61 | BL3: 62 | BM3: 63 | BN3: 64 | BO3: 65 | BP3: 66 | BQ3: 67 | BR3: 68 | BS3: 69 | BT3: 70 | BU3: 71 | BV3: 72 | BW3: 73 | BX3: 74 | BY3: 75 | BZ3: 76 | CA3: 77 | CB3: 78 | CC3: 79 | CD3: 80 | CE3: 81 | CF3: 82 | CG3: 83
B4: θ | C4: 0.1 | D4: 0.2 | E4: 0.3 | F4: 0.4 | G4: 0.5 | H4: 0.6 | I4: 0.7 | J4: 0.8 | K4: 0.9 | L4: 1 | M4: 1.1 | N4: 1.2 | O4: 1.3 | P4: 1.4 | Q4: 1.5 | R4: 1.6 | S4: 1.7 | T4: 1.8 | U4: 1.9 | V4: 2 | W4: 2.1 | X4: 2.2 | Y4: 2.3 | Z4: 2.4 | AA4: 2.5 | AB4: 2.6 | AC4: 2.7 | AD4: 2.8 | AE4: 2.9 | AF4: 3 | AG4: 3.09 | AH4: 3.1
B5: V.out | C5: ='Design Spec'!$D$95 -> 25 | D5: ='Design Spec'!$D$95 -> 25 | E5: ='Design Spec'!$D$95 -> 25 | F5: ='Design Spec'!$D$95 -> 25 | G5: ='Design Spec'!$D$95 -> 25 | H5: ='Design Spec'!$D$95 -> 25 | I5: ='Design Spec'!$D$95 -> 25 | J5: ='Design Spec'!$D$95 -> 25 | ... CG5: ='Design Spec'!$D$95 -> 25
B6: V.f | C6: ='Design Spec'!$D$106 -> 0 | D6: ='Design Spec'!$D$106 -> 0 | E6: ='Design Spec'!$D$106 -> 0 | F6: ='Design Spec'!$D$106 -> 0 | G6: ='Design Spec'!$D$106 -> 0 | H6: ='Design Spec'!$D$106 -> 0 | I6: ='Design Spec'!$D$106 -> 0 | J6: ='Design Spec'!$D$106 -> 0 | ... CG6: ='Design Spec'!$D$106 -> 0
B7: Vin_min | C7: ='Design Spec'!$D$83 -> 173.24116 | D7: ='Design Spec'!$D$83 -> 173.24116 | E7: ='Design Spec'!$D$83 -> 173.24116 | F7: ='Design Spec'!$D$83 -> 173.24116 | G7: ='Design Spec'!$D$83 -> 173.24116 | H7: ='Design Spec'!$D$83 -> 173.24116 | I7: ='Design Spec'!$D$83 -> 173.24116 | J7: ='Design Spec'!$D$83 -> 173.24116 | ... CG7: ='Design Spec'!$D$83 -> 173.24116
B8: Vin_nom | C8: ='Design Spec'!$D$87 -> 225 | D8: ='Design Spec'!$D$87 -> 225 | E8: ='Design Spec'!$D$87 -> 225 | F8: ='Design Spec'!$D$87 -> 225 | G8: ='Design Spec'!$D$87 -> 225 | H8: ='Design Spec'!$D$87 -> 225 | I8: ='Design Spec'!$D$87 -> 225 | J8: ='Design Spec'!$D$87 -> 225 | ... CG8: ='Design Spec'!$D$87 -> 225
B9: Vin_max (equivalent, = MAX of the AC maximum and the FB morphing corner) | C9: =MAX('Design Spec'!$D$79,'Design Spec'!$D$81) -> 332.34019 | D9: =MAX('Design Spec'!$D$79,'Design Spec'!$D$81) -> 332.34019 | E9: =MAX('Design Spec'!$D$79,'Design Spec'!$D$81) -> 332.34019 | F9: =MAX('Design Spec'!$D$79,'Design Spec'!$D$81) -> 332.34019 | G9: =MAX('Design Spec'!$D$79,'Design Spec'!$D$81) -> 332.34019 | H9: =MAX('Design Spec'!$D$79,'Design Spec'!$D$81) -> 332.34019 | I9: =MAX('Design Spec'!$D$79,'Design Spec'!$D$81) -> 332.34019 | J9: =MAX('Design Spec'!$D$79,'Design Spec'!$D$81) -> 332.34019 | ... CG9: =MAX('Design Spec'!$D$79,'Design Spec'!$D$81) -> 332.34019
B10: n | C10: =IF('Res. Tank Design'!$F$9,'Res. Tank Design'!$F$9,'Res. Tank Design'!$D$9) -> 6.0241 | D10: =IF('Res. Tank Design'!$F$9,'Res. Tank Design'!$F$9,'Res. Tank Design'!$D$9) -> 6.0241 | E10: =IF('Res. Tank Design'!$F$9,'Res. Tank Design'!$F$9,'Res. Tank Design'!$D$9) -> 6.0241 | F10: =IF('Res. Tank Design'!$F$9,'Res. Tank Design'!$F$9,'Res. Tank Design'!$D$9) -> 6.0241 | G10: =IF('Res. Tank Design'!$F$9,'Res. Tank Design'!$F$9,'Res. Tank Design'!$D$9) -> 6.0241 | H10: =IF('Res. Tank Design'!$F$9,'Res. Tank Design'!$F$9,'Res. Tank Design'!$D$9) -> 6.0241 | I10: =IF('Res. Tank Design'!$F$9,'Res. Tank Design'!$F$9,'Res. Tank Design'!$D$9) -> 6.0241 | J10: =IF('Res. Tank Design'!$F$9,'Res. Tank Design'!$F$9,'Res. Tank Design'!$D$9) -> 6.0241 | ... CG10: =IF('Res. Tank Design'!$F$9,'Res. Tank Design'!$F$9,'Res. Tank Design'!$D$9) -> 6.0241
B11: Output Rectifier configuration (1 = CT, 2 = FB) | C11: ='Design Spec'!$D$107 -> 1 | D11: ='Design Spec'!$D$107 -> 1 | E11: ='Design Spec'!$D$107 -> 1 | F11: ='Design Spec'!$D$107 -> 1 | G11: ='Design Spec'!$D$107 -> 1 | H11: ='Design Spec'!$D$107 -> 1 | I11: ='Design Spec'!$D$107 -> 1 | J11: ='Design Spec'!$D$107 -> 1 | ... CG11: ='Design Spec'!$D$107 -> 1
B12: Po-100% | C12: ='Design Spec'!$D$98 -> 657.5 | D12: ='Design Spec'!$D$98 -> 657.5 | E12: ='Design Spec'!$D$98 -> 657.5 | F12: ='Design Spec'!$D$98 -> 657.5 | G12: ='Design Spec'!$D$98 -> 657.5 | H12: ='Design Spec'!$D$98 -> 657.5 | I12: ='Design Spec'!$D$98 -> 657.5 | J12: ='Design Spec'!$D$98 -> 657.5 | ... CG12: ='Design Spec'!$D$98 -> 657.5
B13: Po-75% | C13: =C12/4*3 -> 493.125 | D13: =D12/4*3 -> 493.125 | E13: =E12/4*3 -> 493.125 | F13: =F12/4*3 -> 493.125 | G13: =G12/4*3 -> 493.125 | H13: =H12/4*3 -> 493.125 | I13: =I12/4*3 -> 493.125 | J13: =J12/4*3 -> 493.125 | ... CG13: =CG12/4*3 -> 493.125
B14: Po-50% | C14: =C12/2 -> 328.75 | D14: =D12/2 -> 328.75 | E14: =E12/2 -> 328.75 | F14: =F12/2 -> 328.75 | G14: =G12/2 -> 328.75 | H14: =H12/2 -> 328.75 | I14: =I12/2 -> 328.75 | J14: =J12/2 -> 328.75 | ... CG14: =CG12/2 -> 328.75
B15: Po-25% | C15: =C12/4 -> 164.375 | D15: =D12/4 -> 164.375 | E15: =E12/4 -> 164.375 | F15: =F12/4 -> 164.375 | G15: =G12/4 -> 164.375 | H15: =H12/4 -> 164.375 | I15: =I12/4 -> 164.375 | J15: =J12/4 -> 164.375 | ... CG15: =CG12/4 -> 164.375
B16: Mreq(Vin_min, Vout,θ ) | C16: =2*C$10*(C$5+C$11*C$6)/(SQRT(2)*C7*SIN(C$4)) -> 12.314596 | D16: =2*D$10*(D$5+D$11*D$6)/(SQRT(2)*D7*SIN(D$4)) -> 6.1882131 | E16: =2*E$10*(E$5+E$11*E$6)/(SQRT(2)*E7*SIN(E$4)) -> 4.1601492 | F16: =2*F$10*(F$5+F$11*F$6)/(SQRT(2)*F7*SIN(F$4)) -> 3.1570371 | G16: =2*G$10*(G$5+G$11*G$6)/(SQRT(2)*G7*SIN(G$4)) -> 2.564336 | H16: =2*H$10*(H$5+H$11*H$6)/(SQRT(2)*H7*SIN(H$4)) -> 2.1773214 | I16: =2*I$10*(I$5+I$11*I$6)/(SQRT(2)*I7*SIN(I$4)) -> 1.9083738 | J16: =2*J$10*(J$5+J$11*J$6)/(SQRT(2)*J7*SIN(J$4)) -> 1.7138046 | ... AH16: =2*AH$10*(AH$5+AH$11*AH$6)/(SQRT(2)*AH7*SIN(AH$4)) -> 29.566825
B17: Mreq(Vin_max, Vout,θ ) | C17: =2*C$10*(C$5+C$11*C$6)/(SQRT(2)*C9*SIN(C$4)) -> 6.4193105 | D17: =2*D$10*(D$5+D$11*D$6)/(SQRT(2)*D9*SIN(D$4)) -> 3.2257707 | E17: =2*E$10*(E$5+E$11*E$6)/(SQRT(2)*E9*SIN(E$4)) -> 2.1685884 | F17: =2*F$10*(F$5+F$11*F$6)/(SQRT(2)*F9*SIN(F$4)) -> 1.6456896 | G17: =2*G$10*(G$5+G$11*G$6)/(SQRT(2)*G9*SIN(G$4)) -> 1.3367283 | H17: =2*H$10*(H$5+H$11*H$6)/(SQRT(2)*H9*SIN(H$4)) -> 1.1349867 | I17: =2*I$10*(I$5+I$11*I$6)/(SQRT(2)*I9*SIN(I$4)) -> 0.9947906 | J17: =2*J$10*(J$5+J$11*J$6)/(SQRT(2)*J9*SIN(J$4)) -> 0.89336622 | ... AH17: =2*AH$10*(AH$5+AH$11*AH$6)/(SQRT(2)*AH9*SIN(AH$4)) -> 15.412494
B18: Mreq(Vin_max, Vout,π/2 ) | C18: =2*C10*(C5+C11*C6)/(SQRT(2)*C9*SIN(PI()/2)) -> 0.6408617 | D18: =2*D10*(D5+D11*D6)/(SQRT(2)*D9*SIN(PI()/2)) -> 0.6408617 | E18: =2*E10*(E5+E11*E6)/(SQRT(2)*E9*SIN(PI()/2)) -> 0.6408617 | F18: =2*F10*(F5+F11*F6)/(SQRT(2)*F9*SIN(PI()/2)) -> 0.6408617 | G18: =2*G10*(G5+G11*G6)/(SQRT(2)*G9*SIN(PI()/2)) -> 0.6408617 | H18: =2*H10*(H5+H11*H6)/(SQRT(2)*H9*SIN(PI()/2)) -> 0.6408617 | I18: =2*I10*(I5+I11*I6)/(SQRT(2)*I9*SIN(PI()/2)) -> 0.6408617 | J18: =2*J10*(J5+J11*J6)/(SQRT(2)*J9*SIN(PI()/2)) -> 0.6408617 | ... CG18: =2*CG10*(CG5+CG11*CG6)/(SQRT(2)*CG9*SIN(PI()/2)) -> 0.6408617
B19: P(100% Po,θ ) | C19: =2*C12*(SIN(C4))^2 -> 13.106225 | D19: =2*D12*(SIN(D4))^2 -> 51.902396 | E19: =2*E12*(SIN(E4))^2 -> 114.84183 | F19: =2*F12*(SIN(F4))^2 -> 199.41534 | G19: =2*G12*(SIN(G4))^2 -> 302.25123 | H19: =2*H12*(SIN(H4))^2 -> 419.24978 | I19: =2*I12*(SIN(I4))^2 -> 545.7466 | J19: =2*J12*(SIN(J4))^2 -> 676.69869 | ... AH19: =2*AH12*(SIN(AH4))^2 -> 2.2735712
B20: P(75% Po,θ ) | C20: =2*C13*(SIN(C4))^2 -> 9.8296688 | D20: =2*D13*(SIN(D4))^2 -> 38.926797 | E20: =2*E13*(SIN(E4))^2 -> 86.131375 | F20: =2*F13*(SIN(F4))^2 -> 149.5615 | G20: =2*G13*(SIN(G4))^2 -> 226.68843 | H20: =2*H13*(SIN(H4))^2 -> 314.43733 | I20: =2*I13*(SIN(I4))^2 -> 409.30995 | J20: =2*J13*(SIN(J4))^2 -> 507.52401 | ... AH20: =2*AH13*(SIN(AH4))^2 -> 1.7051784
B21: P(50% Po,θ ) | C21: =2*C14*(SIN(C4))^2 -> 6.5531125 | D21: =2*D14*(SIN(D4))^2 -> 25.951198 | E21: =2*E14*(SIN(E4))^2 -> 57.420917 | F21: =2*F14*(SIN(F4))^2 -> 99.707669 | G21: =2*G14*(SIN(G4))^2 -> 151.12562 | H21: =2*H14*(SIN(H4))^2 -> 209.62489 | I21: =2*I14*(SIN(I4))^2 -> 272.8733 | J21: =2*J14*(SIN(J4))^2 -> 338.34934 | ... AH21: =2*AH14*(SIN(AH4))^2 -> 1.1367856
B22: P(25% Po,θ ) | C22: =2*C15*(SIN(C4))^2 -> 3.2765563 | D22: =2*D15*(SIN(D4))^2 -> 12.975599 | E22: =2*E15*(SIN(E4))^2 -> 28.710458 | F22: =2*F15*(SIN(F4))^2 -> 49.853835 | G22: =2*G15*(SIN(G4))^2 -> 75.562808 | H22: =2*H15*(SIN(H4))^2 -> 104.81244 | I22: =2*I15*(SIN(I4))^2 -> 136.43665 | J22: =2*J15*(SIN(J4))^2 -> 169.17467 | ... AH22: =2*AH15*(SIN(AH4))^2 -> 0.5683928
B23: λ | C23: ='Res. Tank Design'!$D$50 -> 0.55 | D23: ='Res. Tank Design'!$D$50 -> 0.55 | E23: ='Res. Tank Design'!$D$50 -> 0.55 | F23: ='Res. Tank Design'!$D$50 -> 0.55 | G23: ='Res. Tank Design'!$D$50 -> 0.55 | H23: ='Res. Tank Design'!$D$50 -> 0.55 | I23: ='Res. Tank Design'!$D$50 -> 0.55 | J23: ='Res. Tank Design'!$D$50 -> 0.55 | ... CG23: ='Res. Tank Design'!$D$50 -> 0.55
B24: fn.0 | C24: ='Res. Tank Design'!$D$56/'Res. Tank Design'!$D$55 -> 0.5956834 | D24: ='Res. Tank Design'!$D$56/'Res. Tank Design'!$D$55 -> 0.5956834 | E24: ='Res. Tank Design'!$D$56/'Res. Tank Design'!$D$55 -> 0.5956834 | F24: ='Res. Tank Design'!$D$56/'Res. Tank Design'!$D$55 -> 0.5956834 | G24: ='Res. Tank Design'!$D$56/'Res. Tank Design'!$D$55 -> 0.5956834 | H24: ='Res. Tank Design'!$D$56/'Res. Tank Design'!$D$55 -> 0.5956834 | I24: ='Res. Tank Design'!$D$56/'Res. Tank Design'!$D$55 -> 0.5956834 | J24: ='Res. Tank Design'!$D$56/'Res. Tank Design'!$D$55 -> 0.5956834 | ... CG24: ='Res. Tank Design'!$D$56/'Res. Tank Design'!$D$55 -> 0.5956834
B25: fn | C25: 0.0001 | D25: =IF(OR(E25<=D24,E25-1/69>D24),E25-1/69,D24-0.0001) -> 0.015873252 | E25: =IF(OR(F25<=E24,F25-1/69>E24),F25-1/69,E24-0.0001) -> 0.030366006 | F25: =IF(OR(G25<=F24,G25-1/69>F24),G25-1/69,F24-0.0001) -> 0.04485876 | G25: =IF(OR(H25<=G24,H25-1/69>G24),H25-1/69,G24-0.0001) -> 0.059351513 | H25: =IF(OR(I25<=H24,I25-1/69>H24),I25-1/69,H24-0.0001) -> 0.073844267 | I25: =IF(OR(J25<=I24,J25-1/69>I24),J25-1/69,I24-0.0001) -> 0.08833702 | J25: =IF(OR(K25<=J24,K25-1/69>J24),K25-1/69,J24-0.0001) -> 0.10282977 | K25: =IF(OR(L25<=K24,L25-1/69>K24),L25-1/69,K24-0.0001) -> 0.11732253 | ... BS25: =IF(OR(BT25<=BS24,BT25-1/69>BS24),BT25-1/69,BS24-0.0001) -> 0.98550725 | BT25: =($CG$25-1)*(BT3-70)/($CG$3-70)+1 -> 1 | BU25: =($CG$25-1)*(BU3-70)/($CG$3-70)+1 -> 1.0941598 | BV25: =($CG$25-1)*(BV3-70)/($CG$3-70)+1 -> 1.1883197 | BW25: =($CG$25-1)*(BW3-70)/($CG$3-70)+1 -> 1.2824795 | BX25: =($CG$25-1)*(BX3-70)/($CG$3-70)+1 -> 1.3766393 | BY25: =($CG$25-1)*(BY3-70)/($CG$3-70)+1 -> 1.4707992 | BZ25: =($CG$25-1)*(BZ3-70)/($CG$3-70)+1 -> 1.564959 | CA25: =($CG$25-1)*(CA3-70)/($CG$3-70)+1 -> 1.6591189 | ... CF25: =($CG$25-1)*(CF3-70)/($CG$3-70)+1 -> 2.129918 | CG25: =1.5*$CG$26 -> 2.2240779
B26: fn.max (no-load crossing; falls back to the CG26 ceiling when the required gain is below the 1/(1+lambda) asymptote) | C26: =IF(1+C23-1/C18>0,SQRT(C23/(1+C23-1/C18)),$CG$26) -> 1.4827186 | D26: =IF(1+D23-1/D18>0,SQRT(D23/(1+D23-1/D18)),$CG$26) -> 1.4827186 | E26: =IF(1+E23-1/E18>0,SQRT(E23/(1+E23-1/E18)),$CG$26) -> 1.4827186 | F26: =IF(1+F23-1/F18>0,SQRT(F23/(1+F23-1/F18)),$CG$26) -> 1.4827186 | G26: =IF(1+G23-1/G18>0,SQRT(G23/(1+G23-1/G18)),$CG$26) -> 1.4827186 | H26: =IF(1+H23-1/H18>0,SQRT(H23/(1+H23-1/H18)),$CG$26) -> 1.4827186 | I26: =IF(1+I23-1/I18>0,SQRT(I23/(1+I23-1/I18)),$CG$26) -> 1.4827186 | J26: =IF(1+J23-1/J18>0,SQRT(J23/(1+J23-1/J18)),$CG$26) -> 1.4827186 | ... CF26: =IF(1+CF23-1/CF18>0,SQRT(CF23/(1+CF23-1/CF18)),$CG$26) -> 1.4827186 | CG26: =MAX(IF(1+$C$23-1/$C$18>0,SQRT($C$23/(1+$C$23-1/$C$18)),0),(SQRT(MAX(0,1/$C$18^2-(1+$C$23)^2))/$C$41+SQRT(SQRT(MAX(0,1/$C$18^2-(1+$C$23)^2))/$C$41^2+4))/2,'Design Spec'!$D$43/'Res. Tank Design'!$D$55) -> 1.4827186
B27: fmax | C27: =C26*'Res. Tank Design'!$D$55 -> 225 | D27: =D26*'Res. Tank Design'!$D$55 -> 225 | E27: =E26*'Res. Tank Design'!$D$55 -> 225 | F27: =F26*'Res. Tank Design'!$D$55 -> 225 | G27: =G26*'Res. Tank Design'!$D$55 -> 225 | H27: =H26*'Res. Tank Design'!$D$55 -> 225 | I27: =I26*'Res. Tank Design'!$D$55 -> 225 | J27: =J26*'Res. Tank Design'!$D$55 -> 225 | ... CG27: =CG26*'Res. Tank Design'!$D$55 -> 225
B28: M.OL(fn) | C28: =1/ABS(1+C23-(C23/(C25^2))) -> 1.8181819e-08 | D28: =1/ABS(1+D23-(D23/(D25^2))) -> 0.00045843486 | E28: =1/ABS(1+E23-(E23/(E25^2))) -> 0.0016809032 | F28: =1/ABS(1+F23-(F23/(F25^2))) -> 0.0036796096 | G28: =1/ABS(1+G23-(G23/(G25^2))) -> 0.0064689505 | H28: =1/ABS(1+H23-(H23/(H25^2))) -> 0.01006924 | I28: =1/ABS(1+I23-(I23/(I25^2))) -> 0.014507085 | J28: =1/ABS(1+J23-(J23/(J25^2))) -> 0.019815887 | ... CG28: =1/ABS(1+CG23-(CG23/(CG25^2))) -> 0.69501843
B29: M.Z(fn) | C29: =IF(D30>C30,NA(),(IF(C30<1,NA(),C30))) -> #N/A | D29: =IF(E30>D30,NA(),(IF(D30<1,NA(),D30))) -> #N/A | E29: =IF(F30>E30,NA(),(IF(E30<1,NA(),E30))) -> #N/A | F29: =IF(G30>F30,NA(),(IF(F30<1,NA(),F30))) -> #N/A | G29: =IF(H30>G30,NA(),(IF(G30<1,NA(),G30))) -> #N/A | H29: =IF(I30>H30,NA(),(IF(H30<1,NA(),H30))) -> #N/A | I29: =IF(J30>I30,NA(),(IF(I30<1,NA(),I30))) -> #N/A | J29: =IF(K30>J30,NA(),(IF(J30<1,NA(),J30))) -> #N/A | ... CG29: =IF(CH30>CG30,NA(),(IF(CG30<1,NA(),CG30))) -> #N/A
C30: =IFERROR(C25/((((C25^2)*(1+C23))-C23)^0.5),C28) -> 1.8181819e-08 | D30: =IFERROR(D25/((((D25^2)*(1+D23))-D23)^0.5),D28) -> 0.00045843486 | E30: =IFERROR(E25/((((E25^2)*(1+E23))-E23)^0.5),E28) -> 0.0016809032 | F30: =IFERROR(F25/((((F25^2)*(1+F23))-F23)^0.5),F28) -> 0.0036796096 | G30: =IFERROR(G25/((((G25^2)*(1+G23))-G23)^0.5),G28) -> 0.0064689505 | H30: =IFERROR(H25/((((H25^2)*(1+H23))-H23)^0.5),H28) -> 0.01006924 | I30: =IFERROR(I25/((((I25^2)*(1+I23))-I23)^0.5),I28) -> 0.014507085 | J30: =IFERROR(J25/((((J25^2)*(1+J23))-J23)^0.5),J28) -> 0.019815887 | ... CG30: =IFERROR(CG25/((((CG25^2)*(1+CG23))-CG23)^0.5),CG28) -> 0.83367765
B31: Minf | C31: =1/(1+C23) -> 0.64516129 | D31: =1/(1+D23) -> 0.64516129 | E31: =1/(1+E23) -> 0.64516129 | F31: =1/(1+F23) -> 0.64516129 | G31: =1/(1+G23) -> 0.64516129 | H31: =1/(1+H23) -> 0.64516129 | I31: =1/(1+I23) -> 0.64516129 | J31: =1/(1+J23) -> 0.64516129 | ... CG31: =1/(1+CG23) -> 0.64516129
B33: π/2 | C33: =PI()/2 -> 1.5707963 | D33: =PI()/2 -> 1.5707963 | E33: =PI()/2 -> 1.5707963 | F33: =PI()/2 -> 1.5707963 | G33: =PI()/2 -> 1.5707963 | H33: =PI()/2 -> 1.5707963 | I33: =PI()/2 -> 1.5707963 | J33: =PI()/2 -> 1.5707963 | ... CG33: =PI()/2 -> 1.5707963
B34: 5π/12 | C34: =5*PI()/12 -> 1.3089969 | D34: =5*PI()/12 -> 1.3089969 | E34: =5*PI()/12 -> 1.3089969 | F34: =5*PI()/12 -> 1.3089969 | G34: =5*PI()/12 -> 1.3089969 | H34: =5*PI()/12 -> 1.3089969 | I34: =5*PI()/12 -> 1.3089969 | J34: =5*PI()/12 -> 1.3089969 | ... CG34: =5*PI()/12 -> 1.3089969
B35: π/3 | C35: =PI()/3 -> 1.0471976 | D35: =PI()/3 -> 1.0471976 | E35: =PI()/3 -> 1.0471976 | F35: =PI()/3 -> 1.0471976 | G35: =PI()/3 -> 1.0471976 | H35: =PI()/3 -> 1.0471976 | I35: =PI()/3 -> 1.0471976 | J35: =PI()/3 -> 1.0471976 | ... CG35: =PI()/3 -> 1.0471976
B36: π/4 | C36: =PI()/4 -> 0.78539816 | D36: =PI()/4 -> 0.78539816 | E36: =PI()/4 -> 0.78539816 | F36: =PI()/4 -> 0.78539816 | G36: =PI()/4 -> 0.78539816 | H36: =PI()/4 -> 0.78539816 | I36: =PI()/4 -> 0.78539816 | J36: =PI()/4 -> 0.78539816 | ... CG36: =PI()/4 -> 0.78539816
B37: π/6 | C37: =PI()/6 -> 0.52359878 | D37: =PI()/6 -> 0.52359878 | E37: =PI()/6 -> 0.52359878 | F37: =PI()/6 -> 0.52359878 | G37: =PI()/6 -> 0.52359878 | H37: =PI()/6 -> 0.52359878 | I37: =PI()/6 -> 0.52359878 | J37: =PI()/6 -> 0.52359878 | ... CG37: =PI()/6 -> 0.52359878
B38: π/12 | C38: =PI()/12 -> 0.26179939 | D38: =PI()/12 -> 0.26179939 | E38: =PI()/12 -> 0.26179939 | F38: =PI()/12 -> 0.26179939 | G38: =PI()/12 -> 0.26179939 | H38: =PI()/12 -> 0.26179939 | I38: =PI()/12 -> 0.26179939 | J38: =PI()/12 -> 0.26179939 | ... CG38: =PI()/12 -> 0.26179939
B39: η.HB | C39: ='Preliminary Calculation'!$D$17 -> 98 | D39: ='Preliminary Calculation'!$D$17 -> 98 | E39: ='Preliminary Calculation'!$D$17 -> 98 | F39: ='Preliminary Calculation'!$D$17 -> 98 | G39: ='Preliminary Calculation'!$D$17 -> 98 | H39: ='Preliminary Calculation'!$D$17 -> 98 | I39: ='Preliminary Calculation'!$D$17 -> 98 | J39: ='Preliminary Calculation'!$D$17 -> 98 | ... CG39: ='Preliminary Calculation'!$D$17 -> 98
B40: Z0 | C40: ='Res. Tank Design'!$D$52 -> 10.488088 | D40: ='Res. Tank Design'!$D$52 -> 10.488088 | E40: ='Res. Tank Design'!$D$52 -> 10.488088 | F40: ='Res. Tank Design'!$D$52 -> 10.488088 | G40: ='Res. Tank Design'!$D$52 -> 10.488088 | H40: ='Res. Tank Design'!$D$52 -> 10.488088 | I40: ='Res. Tank Design'!$D$52 -> 10.488088 | J40: ='Res. Tank Design'!$D$52 -> 10.488088 | ... CG40: ='Res. Tank Design'!$D$52 -> 10.488088
B41: Q(Po,π/2 ) | C41: =(C$40/(C$10^2))*((PI()^2)/4)*(C$12*100/C$39)*(((SIN(C33))^2)/(C$5+C$11*C$6)^2) -> 0.76549334 | D41: =(D$40/(D$10^2))*((PI()^2)/4)*(D$12*100/D$39)*(((SIN(D33))^2)/(D$5+D$11*D$6)^2) -> 0.76549334 | E41: =(E$40/(E$10^2))*((PI()^2)/4)*(E$12*100/E$39)*(((SIN(E33))^2)/(E$5+E$11*E$6)^2) -> 0.76549334 | F41: =(F$40/(F$10^2))*((PI()^2)/4)*(F$12*100/F$39)*(((SIN(F33))^2)/(F$5+F$11*F$6)^2) -> 0.76549334 | G41: =(G$40/(G$10^2))*((PI()^2)/4)*(G$12*100/G$39)*(((SIN(G33))^2)/(G$5+G$11*G$6)^2) -> 0.76549334 | H41: =(H$40/(H$10^2))*((PI()^2)/4)*(H$12*100/H$39)*(((SIN(H33))^2)/(H$5+H$11*H$6)^2) -> 0.76549334 | I41: =(I$40/(I$10^2))*((PI()^2)/4)*(I$12*100/I$39)*(((SIN(I33))^2)/(I$5+I$11*I$6)^2) -> 0.76549334 | J41: =(J$40/(J$10^2))*((PI()^2)/4)*(J$12*100/J$39)*(((SIN(J33))^2)/(J$5+J$11*J$6)^2) -> 0.76549334 | ... CG41: =(CG$40/(CG$10^2))*((PI()^2)/4)*(CG$12*100/CG$39)*(((SIN(CG33))^2)/(CG$5+CG$11*CG$6)^2) -> 0.76549334
B42: Q(Po,5π/12 ) | C42: =(C$40/(C$10^2))*((PI()^2)/4)*(C$12*100/C$39)*(((SIN(C34))^2)/(C$5+C$11*C$6)^2) -> 0.71421501 | D42: =(D$40/(D$10^2))*((PI()^2)/4)*(D$12*100/D$39)*(((SIN(D34))^2)/(D$5+D$11*D$6)^2) -> 0.71421501 | E42: =(E$40/(E$10^2))*((PI()^2)/4)*(E$12*100/E$39)*(((SIN(E34))^2)/(E$5+E$11*E$6)^2) -> 0.71421501 | F42: =(F$40/(F$10^2))*((PI()^2)/4)*(F$12*100/F$39)*(((SIN(F34))^2)/(F$5+F$11*F$6)^2) -> 0.71421501 | G42: =(G$40/(G$10^2))*((PI()^2)/4)*(G$12*100/G$39)*(((SIN(G34))^2)/(G$5+G$11*G$6)^2) -> 0.71421501 | H42: =(H$40/(H$10^2))*((PI()^2)/4)*(H$12*100/H$39)*(((SIN(H34))^2)/(H$5+H$11*H$6)^2) -> 0.71421501 | I42: =(I$40/(I$10^2))*((PI()^2)/4)*(I$12*100/I$39)*(((SIN(I34))^2)/(I$5+I$11*I$6)^2) -> 0.71421501 | J42: =(J$40/(J$10^2))*((PI()^2)/4)*(J$12*100/J$39)*(((SIN(J34))^2)/(J$5+J$11*J$6)^2) -> 0.71421501 | ... CG42: =(CG$40/(CG$10^2))*((PI()^2)/4)*(CG$12*100/CG$39)*(((SIN(CG34))^2)/(CG$5+CG$11*CG$6)^2) -> 0.71421501
B43: Q(Po,π/3) | C43: =(C$40/(C$10^2))*((PI()^2)/4)*(C$12*100/C$39)*(((SIN(C35))^2)/(C$5+C$11*C$6)^2) -> 0.57412 | D43: =(D$40/(D$10^2))*((PI()^2)/4)*(D$12*100/D$39)*(((SIN(D35))^2)/(D$5+D$11*D$6)^2) -> 0.57412 | E43: =(E$40/(E$10^2))*((PI()^2)/4)*(E$12*100/E$39)*(((SIN(E35))^2)/(E$5+E$11*E$6)^2) -> 0.57412 | F43: =(F$40/(F$10^2))*((PI()^2)/4)*(F$12*100/F$39)*(((SIN(F35))^2)/(F$5+F$11*F$6)^2) -> 0.57412 | G43: =(G$40/(G$10^2))*((PI()^2)/4)*(G$12*100/G$39)*(((SIN(G35))^2)/(G$5+G$11*G$6)^2) -> 0.57412 | H43: =(H$40/(H$10^2))*((PI()^2)/4)*(H$12*100/H$39)*(((SIN(H35))^2)/(H$5+H$11*H$6)^2) -> 0.57412 | I43: =(I$40/(I$10^2))*((PI()^2)/4)*(I$12*100/I$39)*(((SIN(I35))^2)/(I$5+I$11*I$6)^2) -> 0.57412 | J43: =(J$40/(J$10^2))*((PI()^2)/4)*(J$12*100/J$39)*(((SIN(J35))^2)/(J$5+J$11*J$6)^2) -> 0.57412 | ... CG43: =(CG$40/(CG$10^2))*((PI()^2)/4)*(CG$12*100/CG$39)*(((SIN(CG35))^2)/(CG$5+CG$11*CG$6)^2) -> 0.57412
...

Sheet CC
C3: 0 | D3: 1 | E3: 2 | F3: 3 | G3: 4 | H3: 5 | I3: 6 | J3: 7 | K3: PI/4 | L3: 8 | M3: 9 | N3: 10 | O3: PI/3 | P3: 11 | Q3: 12 | R3: 13 | S3: 14 | T3: 15 | U3: PI/2 | V3: 16 | W3: 17 | X3: 18 | Y3: 19 | Z3: 20 | AA3: 2*PI/3 | AB3: 21 | AC3: 22 | AD3: 23 | AE3: 3*PI/4 | AF3: 24 | AG3: 25 | AH3: 26 | AI3: 27 | AJ3: 28 | AK3: 29 | AL3: 30 | AM3: 31
