Workbook

Sheet Design Spec
I8: Release 1.0
B10: Input data specs. and pre design choices
B12: Parameters | C12: Name | D12: Value | E12: Unit
B13: Minimum Input voltage | C13: VAC.min | D13: 90 | E13: Vac
B14: Maximum Input voltage | C14: VAC.max | D14: 264 | E14: Vac
B15: =IF(D13>(190/SQRT(2)),"Select high mains configuration (1 = FB, 2 = HB)",IF(AND(D13<=(190/SQRT(2)),D14*SQRT(2)>245),"Selected configuration: universal mains range","Select low mains configuration (1 = FB, 2 = HB)")) -> Selected configuration: universal mains range | C15: Config. | D15: 1 | E15: ="-" -> -
B16: Line frequency | C16: fl | D16: 50 | E16: Hz
B17: Minimum Line frequency | C17: fl.min | D17: 47 | E17: Hz
B19: Parameters | C19: Name | D19: Value | E19: Unit | F19: Selected value
B20: Minimum voltage for Res. Tank Design | C20: Vin.min | D20: =IF('Design Spec'!D80=0,IF(2*D13>IF(165>D14/2,165,D14/2),_xlfn.CONCAT(IF(165>D14/2,165,_xlfn.FLOOR.MATH(D14/2)),"-",2*D13),2*D13),D13) -> 165-180 | E20: Vac | F20: 173.24116
B22: Parameters | C22: Name | D22: Value | E22: Unit
B23: Regulated Output Voltage | C23: V.out | D23: 25 | E23: V
B24: Minimum admitted voltage (for hold up req) | C24: Vo_min_adm | D24: 16 | E24: V
B25: Output voltage ripple pk-pk | C25: ∆vout | D25: 10 | E25: %
B26: Hold up capability | C26: Thold | D26: 10 | E26: ms
B27: Maximum Output Power | C27: Pout | D27: 657.5 | E27: W
B28: Expected HB efficiency | C28: ηLLC | D28: 98 | E28: %
B29: Max capacitor height (empty or 0 for unlimited) | C29: h | D29: 25 | E29: mm
B31: Output cap estimation (MCLPR series) | C31: Name | D31: Value | E31: Unit
B32: Output capacitor working voltage | C32: W.V | D32: =OutCap_Sel_DB!V4 -> 50 | E32: V | F32: =IF(D32="","No solution found, increase max height","")
B33: Single capacitor value | C33: Cout.s.est | D33: =OutCap_Sel_DB!W4 -> 4700 | E33: uF
B34: Equivalent Series Resistor | C34: ESR.single | D34: =OutCap_Sel_DB!Z4 -> 0.084656885 | E34: Ω
B35: Case Size diameter | C35: ØD | D35: =OutCap_Sel_DB!X4 -> 30 | E35: mm
B36: Case Size height | C36: h | D36: =OutCap_Sel_DB!Y4 -> 25 | E36: mm
B37: Estimated number of cap | C37: n.Cap | D37: =OutCap_Sel_DB!AA4 -> 8 | E37: -
B38: Expected ouptut cap volume [cm3] | C38: Cap.Volume | D38: =OutCap_Sel_DB!U4 -> 141.37167 | E38: cm3
B40: Parameters | C40: Name | D40: Value | E40: Unit
B41: Upper Resonant Frequency | C41: f.R1 | D41: 150 | E41: kHz
B42: Minimum switching frequency | C42: fsw.min | D42: 50 | E42: kHz
B43: Maximum Switching Frequency (1.5*f.R1 sugg) | C43: fsw.max | D43: =1.5*D41 -> 225 | E43: kHz
B45: Parameters | C45: Name | D45: Value | E45: Unit
B46: Single HB midpoint estimated Cap | C46: c.HB | D46: 800 | E46: pF
B47: Dead Time | C47: t.D | D47: 220 | E47: ns
B48: Parassitic Capacitance | C48: Cp | D48: 2 | E48: nF
B49: EMI filter resistance | C49: R.EMI | D49: 0.15 | E49: Ω
B51: Parameters | C51: Name | D51: Value | E51: Unit
B52: Bridge Rectifier Voltage Drop | C52: Vf.BR | D52: 0.08 | E52: V
B53: Dynamic Resistance (1 diode) | C53: Rd | D53: 0.04 | E53: Ω
B55: Output stage configuration (CT/FB)
B57: Parameters | C57: Name | D57: Value | E57: Unit
...

Sheet Preliminary Calculation
B4: Preliminary Calculations
B6: Parameters | C6: Name | D6: Value | E6: Unit
B7: Output current | C7: Iout | D7: ='Design Spec'!D98/'Design Spec'!D95 -> 26.3 | E7: A
B8: Output rectifier efficiency | C8: η.rect | D8: ='Design Spec'!D95/('Design Spec'!D95+'Design Spec'!D106*'Design Spec'!D107)*100 -> 100 | E8: %
B9: Transformer output power | C9: P.sec | D9: ='Design Spec'!D98/'Preliminary Calculation'!D8*100 -> 657.5 | E9: W
B10: LLC converter input power | C10: P.in.LLC | D10: ='Design Spec'!D98/('Preliminary Calculation'!D8/100*'Design Spec'!D99/100) -> 670.91837 | E10: W
B11: Max mains input rms current | C11: I.in.max | D11: =D10/'Design Spec'!D78 -> 7.4546485 | E11: A
B12: Output rectifier dissipation | C12: P.d.Drect | D12: =('Design Spec'!D98)*((1-'Preliminary Calculation'!D8/100)/('Preliminary Calculation'!D8/100)) -> 0 | E12: W
B13: LLC converter dissipation (trafo+MOS) | C13: P.d.LLC | D13: =(D9)*((1-('Design Spec'!D99/100))/('Design Spec'!D99/100)) -> 13.418367 | E13: W
B14: Bridge rectifier dissipation | C14: P.D.br | D14: =2*((D11*SQRT(2))*2/PI()*'Design Spec'!D108)+2*('Design Spec'!D109*(D11^2)) -> 5.5195894 | E14: W
B15: EMI filter resistance dissipation | C15: P.D.Rin | D15: ='Design Spec'!D114*D11^2 -> 8.3357677 | E15: W
B16: TOTAL power dissipation | C16: P.D | D16: =D15+D14+D13+D12 -> 27.273724 | E16: W
B17: HB converter expected efficiency | C17: η.HB | D17: =('Design Spec'!D98)/('Design Spec'!D98+('Preliminary Calculation'!D13+'Preliminary Calculation'!D12))*100 -> 98 | E17: %
B18: EMI filter and bridge rectifier efficiency | C18: η.ac | D18: =D10/(D10+(D15+D14))*100 -> 97.976652 | E18: %
B19: Total expected efficiency | C19: η.tot | D19: =D17*D18/100 -> 96.017119 | E19: %
B20: Rated input power | C20: P.in | D20: ='Design Spec'!D98/D19*100 -> 684.77372 | E20: W

Sheet Res. Tank Design
B4: Resonant Tank Design
B6: FHA-based design
B8: Parameters | C8: Name | D8: Value | E8: Unit | F8: Selected Value
B9: Physical Turn Ratio (npri/nsec): | C9: n | D9: =(SQRT(2)*'Design Spec'!D89)/(2*(('Design Spec'!D95+'Design Spec'!D107*'Design Spec'!D106)/'Design Spec'!D107)) -> 6.045763 | E9: ="-" -> - | F9: 7.4527
B10: Maximum Voltage Gain@Vin.min | C10: M.Vmin.pk | D10: =2*IF(F9,F9,D9)*(('Design Spec'!D95+'Design Spec'!D107*'Design Spec'!D106)/'Design Spec'!D107)/(SQRT(2)*'Design Spec'!D83) -> 1.5209592 | E10: ="-" -> -
B11: Minimum Voltage Gain@Vin.min | C11: M.Vmax.pk | D11: =2*IF(F9,F9,D9)*(('Design Spec'!D95+'Design Spec'!D107*'Design Spec'!D106)/'Design Spec'!D107)/(SQRT(2)*'Design Spec'!D79) -> 0.99807854 | E11: ="-" -> -
B12: Min λ ratio for min gain req | C12: λ.min.1 | D12: =(1/(D11))-1 -> 0.0019251559 | E12: ="-" -> -
B13: Min λ ratio for max freq req | C13: λ.min.2 | D13: =D12/(1-('Design Spec'!D102/'Design Spec'!D104)^2) -> 0.0034652806 | E13: ="-" -> -
B14: Min λ ratio for max freq req (TD) | C14: λ.min.TD | D14: =D12/(1-(((PI()^2)/8)*('Design Spec'!D102/'Design Spec'!D104)^2)) -> 0.0042621304 | E14: ="-" -> -
B15: Min λ ratio for min freq req | C15: λ.min.3 | D15: =(('Design Spec'!$D$103/'Design Spec'!$D$102)^2)/(1-('Design Spec'!$D$103/'Design Spec'!$D$102)^2) -> 0.125 | E15: -
B16: Maximum value | C16: λ | D16: =MAX(D12,D13,D14,D15) -> 0.125 | E16: ="-" -> - | F16: removed 1.2 factor on λ.min.1
B17: Equivalent output impedance | C17: Rac | D17: =((IF(F9,F9,D9))^2)*(4/((PI())^2))*(((('Design Spec'!D95+'Design Spec'!D107*'Design Spec'!D106)/'Design Spec'!D107)^2)/('Preliminary Calculation'!D10)) -> 20.969972 | E17: Ω
B18: For ZVS at Vin.min and max load | C18: QZVS.1 | D18: =IF(D10>1,(D16/D10)*SQRT((1/D16)+((D10^2)/((D10^2)-1))),NA()) -> 0.25677291 | E18: ="-" -> -
B19: For ZVS at Vin.max and zero load | C19: QZVS.2 | D19: =(2/PI())*(D16)*(('Design Spec'!D112*(10^-9))/(D17*'Design Spec'!D111*(10^-12))) -> 1.0435781 | E19: ="-" -> -
B20: For ZVS at Vin.max and zero load | C20: QZVS.3 | D20: =((SQRT((D16*(1+D16))))/(2*IF(F9,F9,D9)))*((SQRT(2)*'Design Spec'!D83)/((('Design Spec'!D95+'Design Spec'!D107*'Design Spec'!D106)/'Design Spec'!D107))) -> 0.24655494 | E20: ="-" -> - | F20: Not used since evaluated at f.o
B22: ZVS condition
B24: Parameters | C24: Name | D24: Value | E24: Unit
B25: Margin to achieve ZVS | C25: ZVSmargin | D25: 15 | E25: %
B26: Selected quality factor | C26: QZVS | D26: =1/(1+(D25/100))*MIN(D18:D19) -> 0.22328079 | E26: ="-" -> -
B27: Resonant tank characteristic imp | C27: Z0 | D27: =D17*D26 -> 4.682192 | E27: Ω
B28: Minimum fsw.norm at Vin.min.pk | C28: f.n.min | D28: =1/SQRT((1)+((1/D16)*(1-(1/(D10^(1+(D26/D18)^5)))))) -> 0.45980046 | E28: ="-" -> -
B29: Minimum resonant tank phase shift | C29: φ.min | D29: =ATAN(((((D16^2)+(D16)+(((D28^2)-1)*(D26^2)))*(D28^2))-(D16^2))/(D26*(D28)^3)) -> 0.26084994 | E29: ="-" -> -
B30: Resonant current ZC instant | C30: T.ZC | D30: =(D29)/(2*PI()*D28*'Design Spec'!D102)*1000000 -> 601.93585 | E30: ns
B31: Reference Dead time | C31: T.D | D31: ='Design Spec'!D112 -> 220 | E31: ns
B32: ZVS condition satisfied? | C32: =IF(D30>D31,"Yes","No, increase ZVS margin") -> Yes
B34: Parameters | C34: Name | D34: Value | E34: Unit
B35: Peak Resonant Current | C35: IR1.pk | D35: =(PI()*'Design Spec'!D98)/(SQRT(2)*('Preliminary Calculation'!D17/100)*'Design Spec'!D83*COS('Res. Tank Design'!D29)) -> 8.9042924 | E35: A
B36: Minimum current for achieving ZVS | C36: IR0 | D36: =D35*SIN(D29) -> 2.2964333 | E36: A
B37: Transition time | C37: T.T | D37: ='Design Spec'!D111*(10^-12)*(SQRT(2)*'Design Spec'!D83/'Res. Tank Design'!D36)*10^9 -> 85.349745 | E37: ns
B39: Resonant Tank Parameters
B41: Parameters | C41: Name | D41: Value | E41: Unit | F41: Selected Value
B42: Turn Ratio | C42: n | D42: =IF(F9,F9,D9) -> 7.4527 | E42: ="-" -> -
B43: Resonant Capacitor | C43: C.r | D43: =1/(2*PI()*'Design Spec'!D102*'Res. Tank Design'!D27)*1000000 -> 226.61031 | E43: nF | F43: 100
B44: Leakage inductance | C44: L.r | D44: =1/(IF(F43,F43,D43)*(10^-12)*(2*PI()*'Design Spec'!D102*1000)^2)*1000 -> 11.257909 | E44: µH | F44: 11
B45: Magnetizing inductance | C45: L.m | D45: =IF(F44,F44,D44)/D16 -> 88 | E45: µH | F45: 24
B47: Final Design Check
B49: Parameters | C49: Name | D49: Value | E49: Unit
B50: Series over parallel inductance ratio | C50: λ | D50: =IF(F44,F44,D44)/IF(F45,F45,D45) -> 0.45833333 | E50: ="-" -> -
B51: Real Turn Ratio | C51: n.T | D51: =IF(F9,F9,D9)*(1+D50)^0.5 -> 8.9999903 | E51: ="-" -> -
B52: Series resonant characteristic imp | C52: Z.o | D52: =(IF(F44,F44,D44)/IF(F43,F43,D43)*1000)^0.5 -> 10.488088 | E52: Ω
...

Sheet Power Components
B4: Input capacitor selection
B6: Parameters | C6: Name | D6: Value | E6: Unit | F6: Selected Value
B7: Minimum Input Cap. | C7: C.in.min | D7: =3*'Preliminary Calculation'!D20 -> 2054.3212 | E7: nF | F7: 2200
B9: Output capacitor selection
B11: Parameter | C11: Name | D11: Value | E11: Unit
B12: Output Power | C12: Pout | D12: ='Design Spec'!D27 -> 657.5 | E12: W
B13: Output current | C13: Iout | D13: ='Preliminary Calculation'!D7 -> 26.3 | E13: A
B14: Regulated output voltage | C14: Vout | D14: ='Design Spec'!D23 -> 25 | E14: V
B15: Minimum admitted voltage | C15: Vo_min_adm | D15: ='Design Spec'!D24 -> 16 | E15: V
B16: Output voltage ripple | C16: Ripple | D16: ='Design Spec'!D25 -> 10 | E16: %
B17: Hold up capability | C17: Thold | D17: ='Design Spec'!D26 -> 10 | E17: ms
B18: Minimum Mains frequency | C18: fl | D18: ='Design Spec'!D17 -> 47 | E18: Hz
B20: Parameter | C20: Name | D20: Value | E20: Unit
B21: Output cap considering ripple pk-pk | C21: Cout1 | D21: =D13/(2*PI()*D18*D14*(D16/100))*10^6 -> 35623.617 | E21: uF
B22: Ouptut cap considering hold up | C22: Cout2 | D22: =(2*D12*D17*(10^-3))/((D14^2)-(D15^2))*10^6 -> 35636.856 | E22: uF
B23: Number of output capacitors | C23: n.Cout | D23: 160 | E23: -
B24: Insert the single capacitor value | C24: Cout.single | D24: 470 | E24: uF
B25: Insert the ESR value of the single capacitor | C25: ESR.single | D25: 30 | E25: mΩ
B26: Total ouptut capacitor Cout | C26: Cout | D26: =D24*D23 -> 75200 | E26: uF
B27: Total ESR of Cout | C27: ESR | D27: =D25/D23 -> 0.1875 | E27: mΩ
B28: Output cap RMS current | C28: I.Cout.RMS | D28: =CC!C31 -> 24.414131 | E28: A
B30: Parameter | C30: Name | D30: Value | E30: Unit
B31: Low frequency ripple voltage pk-pk recalculation | C31: V_Ripple_pk-pk | D31: =D13/(2*PI()*D18*D26*(10^-6)) -> 1.1842958 | E31: V
B32: % Ripple pk-pk on Vout | C32: Ripple pk-pk % | D32: =D31/D14*100 -> 4.7371831 | E32: %
B33: Hold up time recalculation | C33: Thold | D33: =D26/(2*D12)*((D14^2)-(D15^2))/1000 -> 21.101749 | E33: ms
B34: Estimated maximum R&N @ Vinmin | C34: R&N_0 | D34: =D27*CC!$E$24 -> 21.669199 | E34: mV
B35: Maximum allowed R&N @ fsw | C35: R&N_max | D35: 30 | E35: mV
B36: Displacement factor of ceramic capacitor | C36: DF | D36: 2.5 | E36: %
B37: Suggested minimum ceramic capacitor | C37: Cceramic min | D37: =IF((1-D35/D34)*(D36/100)*(10^6)/(D27*2*PI()*CC!$E$21*D35/D34)>0,(1-D35/D34)*(D36/100)*(10^6)/(D27*2*PI()*CC!$E$21*D35/D34),0) -> 0 | E37: uF
B38: Select the ceramic capacitor | C38: Cceramic | D38: 10 | E38: uF
B39: Estimated R&N @ fsw | C39: R&N | D39: =D34/(D27*10^(-6)*2*PI()*CC!$E$21*D38/(D36/100)+1) -> 20.615254 | E39: mV
B40: Estimated dissipated power on output capacitors | C40: P.Cout | D40: =D28*D28*(((2*PI()*CC!C21*1000*D38*10^-6)/(D36/100))+(D27/1000)^-1)^-1 -> 0.10670301 | E40: W
B42: Input Bridge Rectifier
B44: Parameter | C44: Name | D44: Value | E44: Unit
B45: Maximum RMS Input Current | C45: Iin | D45: ='Preliminary Calculation'!D11 -> 7.4546485 | E45: A
B46: Parameter | C46: Name | D46: Value | E46: Unit
B47: Selected Bridge Forward Voltage (1 diode) | C47: Vth | D47: ='Design Spec'!D52 -> 0.08 | E47: V
B48: Dynamic Resistance (1 diode) | C48: Rd | D48: ='Design Spec'!D53 -> 0.04 | E48: Ω | G48: Bridge rectifier schematic
G49: =C50 -> GBJ1506U
B50: Please Select a BRIDGE RECTIFIER part number | C50: GBJ1506U
...

Sheet Device Setting
B1: Minimum switching frequency = lower resonant frequency | C1: f.sw.min | D1: ='Res. Tank Design'!D56 -> 85.071895 | E1: kHz
B2: Maximum switching frequency at Vinmax and max load | C2: f.sw.max | D2: =RTC!$BD$212 -> 152.08937 | E2: kHz
B3: Maximum switching frequency for component design | C3: f.sw.max.design | D3: =MIN('Design Spec'!D104,D2*1.5) -> 225 | E3: kHz
B4: Resonant Frequency | C4: f.r | D4: ='Res. Tank Design'!D55 -> 151.74828 | E4: kHz
B10: 1-VCO timing components setting
B12: DS_Reference voltage for CT Typ. | C12: VREF | D12: 1.5 | E12: V
B13: DS_Oscillator idle time 350ns Typ. | C13: Tidle | D13: 350 | E13: ns
B14: DS_Timing resistor operating range [5-30]kΩ | C14: Rtmax | D14: 30 | E14: kΩ
B15: DS_IEA_max typ. 400uA | C15: I.CTL.max | D15: 0.4 | E15: mA
B16: DS_Extra osccillator current at start-up: | C16: IOSC.SU | D16: 0.412 | E16: mA
B18: Parameters | C18: Name | D18: Value | E18: Unit | I18: VCO block diagram
B19: Maximum Timing Capacitor | C19: CT.max | D19: =(D15*(10^-3))*((2*D13*D3*(10^-6))-1)*((2*D13*D1*((10^-6)))-1)/(2*D12*((D3-D1)*10^3))*10^12 -> 754.98662 | E19: pF
B20: Minimum Timing Capacitor | C20: CT.min | D20: =(1/(D14*(10^3)))*((1/(2*D1*10^3))-(D13*(10^-9)))*10^12 -> 184.24606 | E20: pF
B21: Select the timing capacitor between CTmin and Ctmax | C21: CT | D21: 470 | E21: pF
B23: Parameters | C23: Name | D23: Value | E23: Unit | F23: Selected Value
B24: Minimum Resistor value | C24: RT.min | D24: =(1/(D21*(10^-12)))*(1/(2*D1*(10^3))-(D13*10^-9))/1000 -> 11.760387 | E24: kΩ | F24: 11
B26: Parameters | C26: Name | D26: Value | E26: Unit
B27: Actual Max. switching frequency | C27: f.Max | D27: =1/(2*(((D21*(10^-12))/(((D15*(10^-3))/D12)+(1/(F24*(10^3)))))+(D13*(10^-9))))/1000 -> 300.40733 | E27: kHz
B28: Actual Min. switching frequency | C28: f.Min | D28: =1/(2*(D21*F24*(10^-9)+D13*(10^-9)))/1000 -> 90.57971 | E28: kHz
B29: Actual Start-up switching frequency | C29: f.start-up | D29: =1/(2*(((D21*(10^-12))/((((D15+D16)*(10^-3))/(D12))+(1/(F24*(10^3)))))+(D13*(10^-9))))/1000 -> 457.29516 | E29: kHz
C31: P.in | D31: ='Preliminary Calculation'!D20 -> 684.77372 | E31: W
C32: Ilr.pk.max | D32: =CC!E27 -> 15.507005 | E32: A
B33: Maximum rms current on sense resistor (at Vinmin) | C33: I.Rcs.rms.max | D33: =MAX(CC!C29,'Preliminary Calculation'!D11) -> 10.398379 | E33: A
B35: 2-ISEN (Pin6) Current sense resistor calculation
B37: Parameters | C37: Name | D37: Value | E37: Unit
B38: Max input power at FB voltage clamped to the VFB.max | C38: R.CS.max1 | D38: =16.8/D31*1000 -> 24.533652 | E38: mΩ
B39: Minimum input voltage, the maximum input peak current | C39: R.CS.max2 | D39: =0.55/D32*1000 -> 35.467841 | E39: mΩ
B40: Sense dissipation @ low mains | C40: P.Rcs.avg | D40: =(MIN(D38,D39)/1000)*(D33)^2 -> 2.6527326 | E40: W
B41: Single sense resistor maximum power dissipation | C41: P.Rcs.sing | D41: 1 | E41: W
B42: Minimum number or parallel sense resistors | C42: N.Rcs.sing | D42: =_xlfn.CEILING.MATH(D40/D41) -> 3 | E42: -
B43: Select number of parallel sense resistors | C43: N.Rcs.parall | D43: 5 | E43: -
B44: Maximum value of single sense resistor | C44: Max.Rcs.parall | D44: =MIN(D38,D39)*D43 -> 122.66826 | E44: mΩ
B45: Select current sense resistor | C45: R.CS.single | D45: 120 | E45: mΩ | F45: 220||220||220||(220+220) | I45: =D43*((180^-1+180^-1+240^-1)^-1) -> 327.27273 | J45: 180||180||240
B46: Current sense resistor | C46: R.CS | D46: =D45/D43 -> 24 | E46: mΩ
B47: Actual estimated power dissipation on current sense resistor | C47: P.Rcs.act | D47: =(D46/1000)*(D33)^2 -> 2.5950309 | E47: W
B48: Actual estimated maximum input power | C48: Pin.max | D48: =16.8/D46*1000 -> 700 | E48: W
B51: 3-BM (pin10) - Burst mode resistor setting:
B53: DS_BM pin current | C53: I.BM | D53: 13.3 | E53: µA
B54: DS_Scaling factor for burst mode threshold setting | C54: k.BM | D54: 0.01 | E54: V/kΩ
B55: DS_Internal FB offset | C55: V.off | D55: 0.5 | E55: V
...

Sheet CompensationNet&Check
B2: Link input data | C2: Vinmax | D2: ='Design Spec'!D79 -> 264
B3: Link input data | C3: Vinmin | D3: ='Design Spec'!D83 -> 173.24116
B4: Link input data | C4: Vout | D4: ='Design Spec'!D95 -> 25 | E4: V
B5: Link_power components | C5: Cout | D5: ='Power Components'!D26*10^-6 -> 0.0752 | E5: F
B6: Link input data | C6: fl | D6: ='Design Spec'!D90 -> 50 | E6: Hz
B7: Link input data | C7: flmin | D7: ='Design Spec'!D91 -> 47 | E7: Hz
B11: FB and secondary side voltage control loop
B13: Parameters | C13: Name | D13: Value | E13: Unit | H13: Secondary side voltage control loop schematics:
B14: Feedback supply voltage | C14: V.Z | D14: 12 | E14: V
B15: Max feedback current | C15: I.FB.max | D15: =300/D31 -> 566.03774 | E15: µA
B16: Current out of FB pin | C16: I.FB.steady | D16: 150 | E16: µA
B17: FB pin internal resistance | C17: R.FB | D17: 35 | E17: kΩ
B19: Please Select a Voltage Regulator part number | C19: TL431AIT
B21: Parameters | C21: Name | D21: Value | E21: Unit
B22: Tx431 referemce voltage | C22: V.R | D22: 2.495 | E22: V
B23: Tx431 min operating current | C23: I.min | D23: 0.8 | E23: mA
B25: Please Select an Optocoupler part number | C25: SFH617A
B27: Parameters | C27: Name | D27: Value | E27: Unit
B28: Optodiode voltage drop | C28: V.Fo | D28: 1.15 | E28: V
B29: Optocoupler transfer ratio when Itr = 150uA | C29: CTR.steady | D29: 0.37
B30: Optocoupler capacitance | C30: C.opto | D30: 3 | E30: nF
B31: Optocoupler transfer ratio when Itr = 300uA | C31: CTR.max | D31: 0.53 | E31: ="-" -> -
B33: Output feedback divider and Vout setting
B35: Parameters | C35: Name | D35: Value | E35: Unit | F35: Selected value
B36: Upper resistor divider | C36: R.I | D36: 100 | E36: kΩ
B37: Lower resistor divider | C37: Ro | D37: =D22/(D4-D22)*D36 -> 11.086425 | E37: kΩ | F37: 11
B38: Regulated ouput voltage | C38: Vout | D38: =D22*(D36+F37)/F37 -> 25.176818 | E38: V
B40: Parameters | C40: Name | D40: Value | E40: Unit | F40: Selected value
B41: Limiting Resistor | C41: R.p.Max | D41: =D28/D23 -> 1.4375 | E41: kΩ | F41: 1.3
B42: External EA biasing resistor_max value | C42: R.B.max | D42: =(D14-(D22+D28))/(((D16*10^-6)/D29)+(D23*10^-3))/1000 -> 6.931278 | E42: kΩ
B43: External EA biasing resistor_min value | C43: R.B.min | D43: =(D14-(D22+D28))/(((D15*10^-6)/D31)+(D23*10^-3))/1000 -> 4.4727083 | E43: kΩ | F43: 6.2
B44: Maximum Feedback current | C44: I.FB | D44: =((D14-(D22+D28))/(F43*1000)-(D23*10^-3))*D31*(10^6) -> 290.21774 | E44: µA
B46: DS_Gain | C46: K.HV | D46: =3.34*(10^-3) -> 0.00334 | E46: ="-" -> -
B47: DS_Gain | C47: K.M | D47: 0.2 | E47: 1/V^2
B48: DS_Gain | C48: K.FF | D48: 0.2 | E48: V^3
B49: DS_Offset | C49: Vos | D49: 0.5 | E49: V
B51: Link to Preliminary calculations | C51: η.HB | D51: ='Preliminary Calculation'!D17/100 -> 0.98
B52: Link to Device Setting | C52: R.CS | D52: ='Device Setting'!D46*10^(-3) -> 0.024 | E52: Ω
B56: Feedback Loop Requirements
B58: Parameters | C58: Name | D58: Value | E58: Unit
...

Sheet BOM&Schematics
I3: Power Part Schematics
C4: BOM and Schematics
C6: Resonant tank parameters
C8: Parameters | D8: Name | E8: Value | F8: Unit | G8: {=IF(AND(VALUE(E9:E13)),"","Please compile on sheet")}
C9: Magnetizing inductance | D9: L.m | E9: ='Res. Tank Design'!F45 -> 24 | F9: µH | G9: =IF(E9,"","Res. Tank Design")
C10: Leakage inductance | D10: L.r | E10: ='Res. Tank Design'!F44 -> 11 | F10: µH | G10: =IF(E10,"","Res. Tank Design")
C11: Resonant Capacitor | D11: C.r | E11: ='Res. Tank Design'!F43 -> 100 | F11: nF | G11: =IF(E11,"","Res. Tank Design")
C12: Pri. to Sec. turn ratio | D12: n | E12: ='Res. Tank Design'!F9 -> 7.4527 | F12: ="-" -> - | G12: =IF(E12,"","Res. Tank Design")
C13: Auxiliary to Secondary turn ratio | D13: n.aux_sec | E13: ='Device Setting'!$F$83 -> 3 | F13: ="-" -> - | G13: =IF(E13,"","Device Setting")
C15: Input and output cap
C17: Parameters | D17: Name | E17: Value | F17: Unit | G17: {=IF(AND(VALUE(E18:E21)),"","Please compile on sheet")}
C18: PFC input Capacitor | D18: Cin | E18: ='Power Components'!$F$7 -> 2200 | F18: nF | G18: =IF(E18,"","Power Components")
C19: Number of output EL capacitor | D19: n.Cout | E19: ='Power Components'!$D$23 -> 160 | F19: - | G19: =IF(E19,"","Power Components")
C20: PFC Output EL Capacitor (single) | D20: Cout | E20: ='Power Components'!$D$24 -> 470 | F20: µF | G20: =IF(E20,"","Power Components")
C21: PFC Output Ceramic Capcitor | D21: Cout ceramic | E21: ='Power Components'!D38 -> 10 | F21: µF | G21: =IF(E21,"","Power Components")
C23: HVSU connecting diodes PN
C25: Selected component | D25: PN
C26: Example of Diodes PN (x 2) | D26: S1M
C28: Input Bridge Rectifier PN
C30: Selected component | D30: PN
C31: Input Bridge Rectifier PN | D31: ='Power Components'!$C$50 -> GBJ1506U | G31: =IF(ISBLANK(D31),"Power Components","")
C33: Sense resistor
C35: Parameters | D35: Name | E35: Value | F35: Unit | G35: {=IF(AND(VALUE(E36:E38)),"","Please compile on sheet")}
C36: Rsense total value | D36: ='Device Setting'!C$46 -> R.CS | E36: ='Device Setting'!$D$46 -> 24 | F36: mΩ | G36: =IF(E36,"","Device Setting")
C37: Single Rsense value | D37: ='Device Setting'!C$45 -> R.CS.single | E37: ='Device Setting'!D$45 -> 120 | F37: mΩ | G37: =IF(E37,"","Device Setting")
C38: Number of Rsense | D38: ='Device Setting'!C$43 -> N.Rcs.parall | E38: ='Device Setting'!$D$43 -> 5 | F38: mΩ | G38: =IF(E38,"","Device Setting")
C40: Compensation network and Output Divider
C42: Parameters | D42: Name | E42: Value | F42: Unit | G42: {=IF(AND(VALUE(E43:E50)),"","Please compile on sheet")}
C43: Feedback capacitor CFo | D43: C.fo | E43: =IF('CompensationNet&Check'!F93,'CompensationNet&Check'!F93,'CompensationNet&Check'!D93) -> 82 | F43: nF | G43: =IF(E43,"","CompensationNet&Checks")
C44: Feedback capacitor CF | D44: C.f | E44: =IF('CompensationNet&Check'!F94,'CompensationNet&Check'!F94,'CompensationNet&Check'!D94) -> 560 | F44: µF | G44: =IF(E44,"","CompensationNet&Checks")
C45: Feedback resistor RF | D45: R.f | E45: =IF('CompensationNet&Check'!F95,'CompensationNet&Check'!F95,'CompensationNet&Check'!D95) -> 47 | F45: kΩ | G45: =IF(E45,"","CompensationNet&Checks")
C46: feedback capacitor | D46: C.fx | E46: =IF('CompensationNet&Check'!F96,'CompensationNet&Check'!F96,'CompensationNet&Check'!D96) -> 1.55 | F46: nF | G46: =IF(E46,"","CompensationNet&Checks")
C47: Output Voltage upper resistor | D47: R.I | E47: ='CompensationNet&Check'!$D$36 -> 100 | F47: kΩ | G47: =IF(E47,"","CompensationNet&Checks")
C48: Output Voltage lower resistor | D48: R.o | E48: =IF('CompensationNet&Check'!$F$37,'CompensationNet&Check'!$F$37,'CompensationNet&Check'!$D$37) -> 11 | F48: kΩ | G48: =IF(E48,"","CompensationNet&Checks")
C49: Photodiode parallel resistor | D49: R.P | E49: =IF('CompensationNet&Check'!$F$41,'CompensationNet&Check'!$F$41,'CompensationNet&Check'!$D$41) -> 1.3 | F49: kΩ | G49: =IF(E49,"","CompensationNet&Checks")
C50: Bias resistor | D50: R.B | E50: =IF('CompensationNet&Check'!$F$43,'CompensationNet&Check'!$F$43,'CompensationNet&Check'!$D$43) -> 6.2 | F50: kΩ | G50: =IF(E50,"","CompensationNet&Checks") | I50: Controller Part Schematics
C52: L6790 pin configuration
C54: Parameters | D54: Name | E54: Value | F54: Unit | G54: {=IF(AND(VALUE(E55:E60)),"","Please compile on sheet")}
C55: Upper ZCD resistor | D55: R.ZCD.L | E55: =IF('Device Setting'!F90,'Device Setting'!F90,'Device Setting'!D90) -> 19 | F55: kΩ | G55: =IF(E55,"","Device Setting")
C56: Lower ZCD resistor | D56: R.ZCD.H | E56: =IF('Device Setting'!F91,'Device Setting'!F91,'Device Setting'!D91) -> 680 | F56: kΩ | G56: =IF(E56,"","Device Setting")
...

Sheet RTC
C3: 1 | D3: 2 | E3: 3 | F3: 4 | G3: 5 | H3: 6 | I3: 7 | J3: 8 | K3: 9 | L3: 10 | M3: 11 | N3: 12 | O3: 13 | P3: 14 | Q3: 15 | R3: 16 | S3: 17 | T3: 18 | U3: 19 | V3: 20 | W3: 21 | X3: 22 | Y3: 23 | Z3: 24 | AA3: 25 | AB3: 26 | AC3: 27 | AD3: 28 | AE3: 29 | AF3: 30 | AG3: 31 | AH3: 32 | AI3: 33 | AJ3: 34 | AK3: 35 | AL3: 36 | AM3: 37 | AN3: 38 | AO3: 39 | AP3: 40 | AQ3: 41 | AR3: 42 | AS3: 43 | AT3: 44 | AU3: 45 | AV3: 46 | AW3: 47 | AX3: 48 | AY3: 49 | AZ3: 50 | BA3: 51 | BB3: 52 | BC3: 53 | BD3: 54 | BE3: 55 | BF3: 56 | BG3: 57 | BH3: 58 | BI3: 59 | BJ3: 60 | BK3: 61 | BL3: 62 | BM3: 63 | BN3: 64 | BO3: 65 | BP3: 66 | BQ3: 67 | BR3: 68 | BS3: 69 | BT3: 70 | BU3: 71 | BV3: 72 | BW3: 73 | BX3: 74 | BY3: 75 | BZ3: 76 | CA3: 77 | CB3: 78 | CC3: 79 | CD3: 80 | CE3: 81 | CF3: 82 | CG3: 83
B4: θ | C4: 0.1 | D4: 0.2 | E4: 0.3 | F4: 0.4 | G4: 0.5 | H4: 0.6 | I4: 0.7 | J4: 0.8 | K4: 0.9 | L4: 1 | M4: 1.1 | N4: 1.2 | O4: 1.3 | P4: 1.4 | Q4: 1.5 | R4: 1.6 | S4: 1.7 | T4: 1.8 | U4: 1.9 | V4: 2 | W4: 2.1 | X4: 2.2 | Y4: 2.3 | Z4: 2.4 | AA4: 2.5 | AB4: 2.6 | AC4: 2.7 | AD4: 2.8 | AE4: 2.9 | AF4: 3 | AG4: 3.09 | AH4: 3.1
B5: V.out | C5: ='Design Spec'!$D$95 -> 25 | D5: ='Design Spec'!$D$95 -> 25 | E5: ='Design Spec'!$D$95 -> 25 | F5: ='Design Spec'!$D$95 -> 25 | G5: ='Design Spec'!$D$95 -> 25 | H5: ='Design Spec'!$D$95 -> 25 | I5: ='Design Spec'!$D$95 -> 25 | J5: ='Design Spec'!$D$95 -> 25 | ... CG5: ='Design Spec'!$D$95 -> 25
B6: V.f | C6: ='Design Spec'!$D$106 -> 0 | D6: ='Design Spec'!$D$106 -> 0 | E6: ='Design Spec'!$D$106 -> 0 | F6: ='Design Spec'!$D$106 -> 0 | G6: ='Design Spec'!$D$106 -> 0 | H6: ='Design Spec'!$D$106 -> 0 | I6: ='Design Spec'!$D$106 -> 0 | J6: ='Design Spec'!$D$106 -> 0 | ... CG6: ='Design Spec'!$D$106 -> 0
B7: Vin_min | C7: ='Design Spec'!$D$83 -> 173.24116 | D7: ='Design Spec'!$D$83 -> 173.24116 | E7: ='Design Spec'!$D$83 -> 173.24116 | F7: ='Design Spec'!$D$83 -> 173.24116 | G7: ='Design Spec'!$D$83 -> 173.24116 | H7: ='Design Spec'!$D$83 -> 173.24116 | I7: ='Design Spec'!$D$83 -> 173.24116 | J7: ='Design Spec'!$D$83 -> 173.24116 | ... CG7: ='Design Spec'!$D$83 -> 173.24116
B8: Vin_nom | C8: ='Design Spec'!$D$87 -> 225 | D8: ='Design Spec'!$D$87 -> 225 | E8: ='Design Spec'!$D$87 -> 225 | F8: ='Design Spec'!$D$87 -> 225 | G8: ='Design Spec'!$D$87 -> 225 | H8: ='Design Spec'!$D$87 -> 225 | I8: ='Design Spec'!$D$87 -> 225 | J8: ='Design Spec'!$D$87 -> 225 | ... CG8: ='Design Spec'!$D$87 -> 225
B9: Vin_max | C9: ='Design Spec'!$D$79 -> 264 | D9: ='Design Spec'!$D$79 -> 264 | E9: ='Design Spec'!$D$79 -> 264 | F9: ='Design Spec'!$D$79 -> 264 | G9: ='Design Spec'!$D$79 -> 264 | H9: ='Design Spec'!$D$79 -> 264 | I9: ='Design Spec'!$D$79 -> 264 | J9: ='Design Spec'!$D$79 -> 264 | ... CG9: ='Design Spec'!$D$79 -> 264
B10: n | C10: =IF('Res. Tank Design'!$F$9,'Res. Tank Design'!$F$9,'Res. Tank Design'!$D$9) -> 7.4527 | D10: =IF('Res. Tank Design'!$F$9,'Res. Tank Design'!$F$9,'Res. Tank Design'!$D$9) -> 7.4527 | E10: =IF('Res. Tank Design'!$F$9,'Res. Tank Design'!$F$9,'Res. Tank Design'!$D$9) -> 7.4527 | F10: =IF('Res. Tank Design'!$F$9,'Res. Tank Design'!$F$9,'Res. Tank Design'!$D$9) -> 7.4527 | G10: =IF('Res. Tank Design'!$F$9,'Res. Tank Design'!$F$9,'Res. Tank Design'!$D$9) -> 7.4527 | H10: =IF('Res. Tank Design'!$F$9,'Res. Tank Design'!$F$9,'Res. Tank Design'!$D$9) -> 7.4527 | I10: =IF('Res. Tank Design'!$F$9,'Res. Tank Design'!$F$9,'Res. Tank Design'!$D$9) -> 7.4527 | J10: =IF('Res. Tank Design'!$F$9,'Res. Tank Design'!$F$9,'Res. Tank Design'!$D$9) -> 7.4527 | ... CG10: =IF('Res. Tank Design'!$F$9,'Res. Tank Design'!$F$9,'Res. Tank Design'!$D$9) -> 7.4527
B11: Output Rectifier configuration (1 = CT, 2 = FB) | C11: ='Design Spec'!$D$107 -> 1 | D11: ='Design Spec'!$D$107 -> 1 | E11: ='Design Spec'!$D$107 -> 1 | F11: ='Design Spec'!$D$107 -> 1 | G11: ='Design Spec'!$D$107 -> 1 | H11: ='Design Spec'!$D$107 -> 1 | I11: ='Design Spec'!$D$107 -> 1 | J11: ='Design Spec'!$D$107 -> 1 | ... CG11: ='Design Spec'!$D$107 -> 1
B12: Po-100% | C12: ='Design Spec'!$D$98 -> 657.5 | D12: ='Design Spec'!$D$98 -> 657.5 | E12: ='Design Spec'!$D$98 -> 657.5 | F12: ='Design Spec'!$D$98 -> 657.5 | G12: ='Design Spec'!$D$98 -> 657.5 | H12: ='Design Spec'!$D$98 -> 657.5 | I12: ='Design Spec'!$D$98 -> 657.5 | J12: ='Design Spec'!$D$98 -> 657.5 | ... CG12: ='Design Spec'!$D$98 -> 657.5
B13: Po-75% | C13: =C12/4*3 -> 493.125 | D13: =D12/4*3 -> 493.125 | E13: =E12/4*3 -> 493.125 | F13: =F12/4*3 -> 493.125 | G13: =G12/4*3 -> 493.125 | H13: =H12/4*3 -> 493.125 | I13: =I12/4*3 -> 493.125 | J13: =J12/4*3 -> 493.125 | ... CG13: =CG12/4*3 -> 493.125
B14: Po-50% | C14: =C12/2 -> 328.75 | D14: =D12/2 -> 328.75 | E14: =E12/2 -> 328.75 | F14: =F12/2 -> 328.75 | G14: =G12/2 -> 328.75 | H14: =H12/2 -> 328.75 | I14: =I12/2 -> 328.75 | J14: =J12/2 -> 328.75 | ... CG14: =CG12/2 -> 328.75
B15: Po-25% | C15: =C12/4 -> 164.375 | D15: =D12/4 -> 164.375 | E15: =E12/4 -> 164.375 | F15: =F12/4 -> 164.375 | G15: =G12/4 -> 164.375 | H15: =H12/4 -> 164.375 | I15: =I12/4 -> 164.375 | J15: =J12/4 -> 164.375 | ... CG15: =CG12/4 -> 164.375
B16: Mreq(Vin_min, Vout,θ ) | C16: =2*C$10*((C$5+C$11*C$6)/C$11)/(SQRT(2)*C7*SIN(C$4)) -> 15.234971 | D16: =2*D$10*((D$5+D$11*D$6)/D$11)/(SQRT(2)*D7*SIN(D$4)) -> 7.6557322 | E16: =2*E$10*((E$5+E$11*E$6)/E$11)/(SQRT(2)*E7*SIN(E$4)) -> 5.1467181 | F16: =2*F$10*((F$5+F$11*F$6)/F$11)/(SQRT(2)*F7*SIN(F$4)) -> 3.9057205 | G16: =2*G$10*((G$5+G$11*G$6)/G$11)/(SQRT(2)*G7*SIN(G$4)) -> 3.1724618 | H16: =2*H$10*((H$5+H$11*H$6)/H$11)/(SQRT(2)*H7*SIN(H$4)) -> 2.6936677 | I16: =2*I$10*((I$5+I$11*I$6)/I$11)/(SQRT(2)*I7*SIN(I$4)) -> 2.3609398 | J16: =2*J$10*((J$5+J$11*J$6)/J$11)/(SQRT(2)*J7*SIN(J$4)) -> 2.120229 | ... AH16: =2*AH$10*((AH$5+AH$11*AH$6)/AH$11)/(SQRT(2)*AH7*SIN(AH$4)) -> 36.578522
B17: Mreq(Vin_max, Vout,θ ) | C17: =2*C$10*((C$5+C$11*C$6)/C$11)/(SQRT(2)*C9*SIN(C$4)) -> 9.9974395 | D17: =2*D$10*((D$5+D$11*D$6)/D$11)/(SQRT(2)*D9*SIN(D$4)) -> 5.0238179 | E17: =2*E$10*((E$5+E$11*E$6)/E$11)/(SQRT(2)*E9*SIN(E$4)) -> 3.3773614 | F17: =2*F$10*((F$5+F$11*F$6)/F$11)/(SQRT(2)*F9*SIN(F$4)) -> 2.5629983 | G17: =2*G$10*((G$5+G$11*G$6)/G$11)/(SQRT(2)*G9*SIN(G$4)) -> 2.0818218 | H17: =2*H$10*((H$5+H$11*H$6)/H$11)/(SQRT(2)*H9*SIN(H$4)) -> 1.7676292 | I17: =2*I$10*((I$5+I$11*I$6)/I$11)/(SQRT(2)*I9*SIN(I$4)) -> 1.5492877 | J17: =2*J$10*((J$5+J$11*J$6)/J$11)/(SQRT(2)*J9*SIN(J$4)) -> 1.3913293 | ... AH17: =2*AH$10*((AH$5+AH$11*AH$6)/AH$11)/(SQRT(2)*AH9*SIN(AH$4)) -> 24.003431
B18: Mreq(Vin_max, Vout,π/2 ) | C18: =2*C10*((C5+C11*C6)/C11)/(SQRT(2)*C9*SIN(PI()/2)) -> 0.99807854 | D18: =2*D10*((D5+D11*D6)/D11)/(SQRT(2)*D9*SIN(PI()/2)) -> 0.99807854 | E18: =2*E10*((E5+E11*E6)/E11)/(SQRT(2)*E9*SIN(PI()/2)) -> 0.99807854 | F18: =2*F10*((F5+F11*F6)/F11)/(SQRT(2)*F9*SIN(PI()/2)) -> 0.99807854 | G18: =2*G10*((G5+G11*G6)/G11)/(SQRT(2)*G9*SIN(PI()/2)) -> 0.99807854 | H18: =2*H10*((H5+H11*H6)/H11)/(SQRT(2)*H9*SIN(PI()/2)) -> 0.99807854 | I18: =2*I10*((I5+I11*I6)/I11)/(SQRT(2)*I9*SIN(PI()/2)) -> 0.99807854 | J18: =2*J10*((J5+J11*J6)/J11)/(SQRT(2)*J9*SIN(PI()/2)) -> 0.99807854 | ... CG18: =2*CG10*((CG5+CG11*CG6)/CG11)/(SQRT(2)*CG9*SIN(PI()/2)) -> 0.99807854
B19: P(100% Po,θ ) | C19: =2*C12*(SIN(C4))^2 -> 13.106225 | D19: =2*D12*(SIN(D4))^2 -> 51.902396 | E19: =2*E12*(SIN(E4))^2 -> 114.84183 | F19: =2*F12*(SIN(F4))^2 -> 199.41534 | G19: =2*G12*(SIN(G4))^2 -> 302.25123 | H19: =2*H12*(SIN(H4))^2 -> 419.24978 | I19: =2*I12*(SIN(I4))^2 -> 545.7466 | J19: =2*J12*(SIN(J4))^2 -> 676.69869 | ... AH19: =2*AH12*(SIN(AH4))^2 -> 2.2735712
B20: P(75% Po,θ ) | C20: =2*C13*(SIN(C4))^2 -> 9.8296688 | D20: =2*D13*(SIN(D4))^2 -> 38.926797 | E20: =2*E13*(SIN(E4))^2 -> 86.131375 | F20: =2*F13*(SIN(F4))^2 -> 149.5615 | G20: =2*G13*(SIN(G4))^2 -> 226.68843 | H20: =2*H13*(SIN(H4))^2 -> 314.43733 | I20: =2*I13*(SIN(I4))^2 -> 409.30995 | J20: =2*J13*(SIN(J4))^2 -> 507.52401 | ... AH20: =2*AH13*(SIN(AH4))^2 -> 1.7051784
B21: P(50% Po,θ ) | C21: =2*C14*(SIN(C4))^2 -> 6.5531125 | D21: =2*D14*(SIN(D4))^2 -> 25.951198 | E21: =2*E14*(SIN(E4))^2 -> 57.420917 | F21: =2*F14*(SIN(F4))^2 -> 99.707669 | G21: =2*G14*(SIN(G4))^2 -> 151.12562 | H21: =2*H14*(SIN(H4))^2 -> 209.62489 | I21: =2*I14*(SIN(I4))^2 -> 272.8733 | J21: =2*J14*(SIN(J4))^2 -> 338.34934 | ... AH21: =2*AH14*(SIN(AH4))^2 -> 1.1367856
B22: P(25% Po,θ ) | C22: =2*C15*(SIN(C4))^2 -> 3.2765563 | D22: =2*D15*(SIN(D4))^2 -> 12.975599 | E22: =2*E15*(SIN(E4))^2 -> 28.710458 | F22: =2*F15*(SIN(F4))^2 -> 49.853835 | G22: =2*G15*(SIN(G4))^2 -> 75.562808 | H22: =2*H15*(SIN(H4))^2 -> 104.81244 | I22: =2*I15*(SIN(I4))^2 -> 136.43665 | J22: =2*J15*(SIN(J4))^2 -> 169.17467 | ... AH22: =2*AH15*(SIN(AH4))^2 -> 0.5683928
B23: λ | C23: ='Res. Tank Design'!$D$50 -> 0.45833333 | D23: ='Res. Tank Design'!$D$50 -> 0.45833333 | E23: ='Res. Tank Design'!$D$50 -> 0.45833333 | F23: ='Res. Tank Design'!$D$50 -> 0.45833333 | G23: ='Res. Tank Design'!$D$50 -> 0.45833333 | H23: ='Res. Tank Design'!$D$50 -> 0.45833333 | I23: ='Res. Tank Design'!$D$50 -> 0.45833333 | J23: ='Res. Tank Design'!$D$50 -> 0.45833333 | ... CG23: ='Res. Tank Design'!$D$50 -> 0.45833333
B24: fn.0 | C24: ='Res. Tank Design'!$D$56/'Res. Tank Design'!$D$55 -> 0.56061191 | D24: ='Res. Tank Design'!$D$56/'Res. Tank Design'!$D$55 -> 0.56061191 | E24: ='Res. Tank Design'!$D$56/'Res. Tank Design'!$D$55 -> 0.56061191 | F24: ='Res. Tank Design'!$D$56/'Res. Tank Design'!$D$55 -> 0.56061191 | G24: ='Res. Tank Design'!$D$56/'Res. Tank Design'!$D$55 -> 0.56061191 | H24: ='Res. Tank Design'!$D$56/'Res. Tank Design'!$D$55 -> 0.56061191 | I24: ='Res. Tank Design'!$D$56/'Res. Tank Design'!$D$55 -> 0.56061191 | J24: ='Res. Tank Design'!$D$56/'Res. Tank Design'!$D$55 -> 0.56061191 | ... CG24: ='Res. Tank Design'!$D$56/'Res. Tank Design'!$D$55 -> 0.56061191
B25: fn | C25: 0.0001 | D25: =IF(OR(E25<=D24,E25-1/69>D24),E25-1/69,D24-0.0001) -> 0.024280027 | E25: =IF(OR(F25<=E24,F25-1/69>E24),F25-1/69,E24-0.0001) -> 0.03877278 | F25: =IF(OR(G25<=F24,G25-1/69>F24),G25-1/69,F24-0.0001) -> 0.053265534 | G25: =IF(OR(H25<=G24,H25-1/69>G24),H25-1/69,G24-0.0001) -> 0.067758287 | H25: =IF(OR(I25<=H24,I25-1/69>H24),I25-1/69,H24-0.0001) -> 0.082251041 | I25: =IF(OR(J25<=I24,J25-1/69>I24),J25-1/69,I24-0.0001) -> 0.096743795 | J25: =IF(OR(K25<=J24,K25-1/69>J24),K25-1/69,J24-0.0001) -> 0.11123655 | K25: =IF(OR(L25<=K24,L25-1/69>K24),L25-1/69,K24-0.0001) -> 0.1257293 | ... BS25: =IF(OR(BT25<=BS24,BT25-1/69>BS24),BT25-1/69,BS24-0.0001) -> 0.98550725 | BT25: =($CG$25-1)*(BT3-70)/($CG$3-70)+1 -> 1 | BU25: =($CG$25-1)*(BU3-70)/($CG$3-70)+1 -> 1.0387046 | BV25: =($CG$25-1)*(BV3-70)/($CG$3-70)+1 -> 1.0774093 | BW25: =($CG$25-1)*(BW3-70)/($CG$3-70)+1 -> 1.1161139 | BX25: =($CG$25-1)*(BX3-70)/($CG$3-70)+1 -> 1.1548185 | BY25: =($CG$25-1)*(BY3-70)/($CG$3-70)+1 -> 1.1935232 | BZ25: =($CG$25-1)*(BZ3-70)/($CG$3-70)+1 -> 1.2322278 | CA25: =($CG$25-1)*(CA3-70)/($CG$3-70)+1 -> 1.2709324 | ... CF25: =($CG$25-1)*(CF3-70)/($CG$3-70)+1 -> 1.4644556 | CG25: =1.5*$CG$26 -> 1.5031602
B26: fn.max | C26: =(C23/(1+C23-(1/C18)))^0.5 -> 1.0021068 | D26: =(D23/(1+D23-(1/D18)))^0.5 -> 1.0021068 | E26: =(E23/(1+E23-(1/E18)))^0.5 -> 1.0021068 | F26: =(F23/(1+F23-(1/F18)))^0.5 -> 1.0021068 | G26: =(G23/(1+G23-(1/G18)))^0.5 -> 1.0021068 | H26: =(H23/(1+H23-(1/H18)))^0.5 -> 1.0021068 | I26: =(I23/(1+I23-(1/I18)))^0.5 -> 1.0021068 | J26: =(J23/(1+J23-(1/J18)))^0.5 -> 1.0021068 | ... CG26: =(CG23/(1+CG23-(1/CG18)))^0.5 -> 1.0021068
B27: fmax | C27: =C26*'Res. Tank Design'!$D$55 -> 152.06799 | D27: =D26*'Res. Tank Design'!$D$55 -> 152.06799 | E27: =E26*'Res. Tank Design'!$D$55 -> 152.06799 | F27: =F26*'Res. Tank Design'!$D$55 -> 152.06799 | G27: =G26*'Res. Tank Design'!$D$55 -> 152.06799 | H27: =H26*'Res. Tank Design'!$D$55 -> 152.06799 | I27: =I26*'Res. Tank Design'!$D$55 -> 152.06799 | J27: =J26*'Res. Tank Design'!$D$55 -> 152.06799 | ... CG27: =CG26*'Res. Tank Design'!$D$55 -> 152.06799
B28: M.OL(fn) | C28: =1/ABS(1+C23-(C23/(C25^2))) -> 2.1818183e-08 | D28: =1/ABS(1+D23-(D23/(D25^2))) -> 0.0012886419 | E28: =1/ABS(1+E23-(E23/(E25^2))) -> 0.0032957541 | F28: =1/ABS(1+F23-(F23/(F25^2))) -> 0.0062466838 | G28: =1/ABS(1+G23-(G23/(G25^2))) -> 0.010165635 | H28: =1/ABS(1+H23-(H23/(H25^2))) -> 0.015085231 | I28: =1/ABS(1+I23-(I23/(I25^2))) -> 0.021047207 | J28: =1/ABS(1+J23-(J23/(J25^2))) -> 0.02810332 | ... CG28: =1/ABS(1+CG23-(CG23/(CG25^2))) -> 0.79650477
B29: M.Z(fn) | C29: =IF(D30>C30,NA(),(IF(C30<1,NA(),C30))) -> #N/A | D29: =IF(E30>D30,NA(),(IF(D30<1,NA(),D30))) -> #N/A | E29: =IF(F30>E30,NA(),(IF(E30<1,NA(),E30))) -> #N/A | F29: =IF(G30>F30,NA(),(IF(F30<1,NA(),F30))) -> #N/A | G29: =IF(H30>G30,NA(),(IF(G30<1,NA(),G30))) -> #N/A | H29: =IF(I30>H30,NA(),(IF(H30<1,NA(),H30))) -> #N/A | I29: =IF(J30>I30,NA(),(IF(I30<1,NA(),I30))) -> #N/A | J29: =IF(K30>J30,NA(),(IF(J30<1,NA(),J30))) -> #N/A | ... CG29: =IF(CH30>CG30,NA(),(IF(CG30<1,NA(),CG30))) -> #N/A
C30: =IFERROR(C25/((((C25^2)*(1+C23))-C23)^0.5),C28) -> 2.1818183e-08 | D30: =IFERROR(D25/((((D25^2)*(1+D23))-D23)^0.5),D28) -> 0.0012886419 | E30: =IFERROR(E25/((((E25^2)*(1+E23))-E23)^0.5),E28) -> 0.0032957541 | F30: =IFERROR(F25/((((F25^2)*(1+F23))-F23)^0.5),F28) -> 0.0062466838 | G30: =IFERROR(G25/((((G25^2)*(1+G23))-G23)^0.5),G28) -> 0.010165635 | H30: =IFERROR(H25/((((H25^2)*(1+H23))-H23)^0.5),H28) -> 0.015085231 | I30: =IFERROR(I25/((((I25^2)*(1+I23))-I23)^0.5),I28) -> 0.021047207 | J30: =IFERROR(J25/((((J25^2)*(1+J23))-J23)^0.5),J28) -> 0.02810332 | ... CG30: =IFERROR(CG25/((((CG25^2)*(1+CG23))-CG23)^0.5),CG28) -> 0.89247116
B31: Minf | C31: =1/(1+C23) -> 0.68571429 | D31: =1/(1+D23) -> 0.68571429 | E31: =1/(1+E23) -> 0.68571429 | F31: =1/(1+F23) -> 0.68571429 | G31: =1/(1+G23) -> 0.68571429 | H31: =1/(1+H23) -> 0.68571429 | I31: =1/(1+I23) -> 0.68571429 | J31: =1/(1+J23) -> 0.68571429 | ... CG31: =1/(1+CG23) -> 0.68571429
B33: π/2 | C33: =PI()/2 -> 1.5707963 | D33: =PI()/2 -> 1.5707963 | E33: =PI()/2 -> 1.5707963 | F33: =PI()/2 -> 1.5707963 | G33: =PI()/2 -> 1.5707963 | H33: =PI()/2 -> 1.5707963 | I33: =PI()/2 -> 1.5707963 | J33: =PI()/2 -> 1.5707963 | ... CG33: =PI()/2 -> 1.5707963
B34: 5π/12 | C34: =5*PI()/12 -> 1.3089969 | D34: =5*PI()/12 -> 1.3089969 | E34: =5*PI()/12 -> 1.3089969 | F34: =5*PI()/12 -> 1.3089969 | G34: =5*PI()/12 -> 1.3089969 | H34: =5*PI()/12 -> 1.3089969 | I34: =5*PI()/12 -> 1.3089969 | J34: =5*PI()/12 -> 1.3089969 | ... CG34: =5*PI()/12 -> 1.3089969
B35: π/3 | C35: =PI()/3 -> 1.0471976 | D35: =PI()/3 -> 1.0471976 | E35: =PI()/3 -> 1.0471976 | F35: =PI()/3 -> 1.0471976 | G35: =PI()/3 -> 1.0471976 | H35: =PI()/3 -> 1.0471976 | I35: =PI()/3 -> 1.0471976 | J35: =PI()/3 -> 1.0471976 | ... CG35: =PI()/3 -> 1.0471976
B36: π/4 | C36: =PI()/4 -> 0.78539816 | D36: =PI()/4 -> 0.78539816 | E36: =PI()/4 -> 0.78539816 | F36: =PI()/4 -> 0.78539816 | G36: =PI()/4 -> 0.78539816 | H36: =PI()/4 -> 0.78539816 | I36: =PI()/4 -> 0.78539816 | J36: =PI()/4 -> 0.78539816 | ... CG36: =PI()/4 -> 0.78539816
B37: π/6 | C37: =PI()/6 -> 0.52359878 | D37: =PI()/6 -> 0.52359878 | E37: =PI()/6 -> 0.52359878 | F37: =PI()/6 -> 0.52359878 | G37: =PI()/6 -> 0.52359878 | H37: =PI()/6 -> 0.52359878 | I37: =PI()/6 -> 0.52359878 | J37: =PI()/6 -> 0.52359878 | ... CG37: =PI()/6 -> 0.52359878
B38: π/12 | C38: =PI()/12 -> 0.26179939 | D38: =PI()/12 -> 0.26179939 | E38: =PI()/12 -> 0.26179939 | F38: =PI()/12 -> 0.26179939 | G38: =PI()/12 -> 0.26179939 | H38: =PI()/12 -> 0.26179939 | I38: =PI()/12 -> 0.26179939 | J38: =PI()/12 -> 0.26179939 | ... CG38: =PI()/12 -> 0.26179939
B39: η.HB | C39: ='Preliminary Calculation'!$D$17 -> 98 | D39: ='Preliminary Calculation'!$D$17 -> 98 | E39: ='Preliminary Calculation'!$D$17 -> 98 | F39: ='Preliminary Calculation'!$D$17 -> 98 | G39: ='Preliminary Calculation'!$D$17 -> 98 | H39: ='Preliminary Calculation'!$D$17 -> 98 | I39: ='Preliminary Calculation'!$D$17 -> 98 | J39: ='Preliminary Calculation'!$D$17 -> 98 | ... CG39: ='Preliminary Calculation'!$D$17 -> 98
B40: Z0 | C40: ='Res. Tank Design'!$D$52 -> 10.488088 | D40: ='Res. Tank Design'!$D$52 -> 10.488088 | E40: ='Res. Tank Design'!$D$52 -> 10.488088 | F40: ='Res. Tank Design'!$D$52 -> 10.488088 | G40: ='Res. Tank Design'!$D$52 -> 10.488088 | H40: ='Res. Tank Design'!$D$52 -> 10.488088 | I40: ='Res. Tank Design'!$D$52 -> 10.488088 | J40: ='Res. Tank Design'!$D$52 -> 10.488088 | ... CG40: ='Res. Tank Design'!$D$52 -> 10.488088
B41: Q(Po,π/2 ) | C41: =(C$40/(C$10^2))*((PI()^2)/4)*(C$12*100/C$39)*(((SIN(C33))^2)/((C$5+C$11*C$6)/C$11)^2) -> 0.50014794 | D41: =(D$40/(D$10^2))*((PI()^2)/4)*(D$12*100/D$39)*(((SIN(D33))^2)/((D$5+D$11*D$6)/D$11)^2) -> 0.50014794 | E41: =(E$40/(E$10^2))*((PI()^2)/4)*(E$12*100/E$39)*(((SIN(E33))^2)/((E$5+E$11*E$6)/E$11)^2) -> 0.50014794 | F41: =(F$40/(F$10^2))*((PI()^2)/4)*(F$12*100/F$39)*(((SIN(F33))^2)/((F$5+F$11*F$6)/F$11)^2) -> 0.50014794 | G41: =(G$40/(G$10^2))*((PI()^2)/4)*(G$12*100/G$39)*(((SIN(G33))^2)/((G$5+G$11*G$6)/G$11)^2) -> 0.50014794 | H41: =(H$40/(H$10^2))*((PI()^2)/4)*(H$12*100/H$39)*(((SIN(H33))^2)/((H$5+H$11*H$6)/H$11)^2) -> 0.50014794 | I41: =(I$40/(I$10^2))*((PI()^2)/4)*(I$12*100/I$39)*(((SIN(I33))^2)/((I$5+I$11*I$6)/I$11)^2) -> 0.50014794 | J41: =(J$40/(J$10^2))*((PI()^2)/4)*(J$12*100/J$39)*(((SIN(J33))^2)/((J$5+J$11*J$6)/J$11)^2) -> 0.50014794 | ... CG41: =(CG$40/(CG$10^2))*((PI()^2)/4)*(CG$12*100/CG$39)*(((SIN(CG33))^2)/((CG$5+CG$11*CG$6)/CG$11)^2) -> 0.50014794
B42: Q(Po,5π/12 ) | C42: =(C$40/(C$10^2))*((PI()^2)/4)*(C$12*100/C$39)*(((SIN(C34))^2)/((C$5+C$11*C$6)/C$11)^2) -> 0.46664438 | D42: =(D$40/(D$10^2))*((PI()^2)/4)*(D$12*100/D$39)*(((SIN(D34))^2)/((D$5+D$11*D$6)/D$11)^2) -> 0.46664438 | E42: =(E$40/(E$10^2))*((PI()^2)/4)*(E$12*100/E$39)*(((SIN(E34))^2)/((E$5+E$11*E$6)/E$11)^2) -> 0.46664438 | F42: =(F$40/(F$10^2))*((PI()^2)/4)*(F$12*100/F$39)*(((SIN(F34))^2)/((F$5+F$11*F$6)/F$11)^2) -> 0.46664438 | G42: =(G$40/(G$10^2))*((PI()^2)/4)*(G$12*100/G$39)*(((SIN(G34))^2)/((G$5+G$11*G$6)/G$11)^2) -> 0.46664438 | H42: =(H$40/(H$10^2))*((PI()^2)/4)*(H$12*100/H$39)*(((SIN(H34))^2)/((H$5+H$11*H$6)/H$11)^2) -> 0.46664438 | I42: =(I$40/(I$10^2))*((PI()^2)/4)*(I$12*100/I$39)*(((SIN(I34))^2)/((I$5+I$11*I$6)/I$11)^2) -> 0.46664438 | J42: =(J$40/(J$10^2))*((PI()^2)/4)*(J$12*100/J$39)*(((SIN(J34))^2)/((J$5+J$11*J$6)/J$11)^2) -> 0.46664438 | ... CG42: =(CG$40/(CG$10^2))*((PI()^2)/4)*(CG$12*100/CG$39)*(((SIN(CG34))^2)/((CG$5+CG$11*CG$6)/CG$11)^2) -> 0.46664438
B43: Q(Po,π/3) | C43: =(C$40/(C$10^2))*((PI()^2)/4)*(C$12*100/C$39)*(((SIN(C35))^2)/((C$5+C$11*C$6)/C$11)^2) -> 0.37511095 | D43: =(D$40/(D$10^2))*((PI()^2)/4)*(D$12*100/D$39)*(((SIN(D35))^2)/((D$5+D$11*D$6)/D$11)^2) -> 0.37511095 | E43: =(E$40/(E$10^2))*((PI()^2)/4)*(E$12*100/E$39)*(((SIN(E35))^2)/((E$5+E$11*E$6)/E$11)^2) -> 0.37511095 | F43: =(F$40/(F$10^2))*((PI()^2)/4)*(F$12*100/F$39)*(((SIN(F35))^2)/((F$5+F$11*F$6)/F$11)^2) -> 0.37511095 | G43: =(G$40/(G$10^2))*((PI()^2)/4)*(G$12*100/G$39)*(((SIN(G35))^2)/((G$5+G$11*G$6)/G$11)^2) -> 0.37511095 | H43: =(H$40/(H$10^2))*((PI()^2)/4)*(H$12*100/H$39)*(((SIN(H35))^2)/((H$5+H$11*H$6)/H$11)^2) -> 0.37511095 | I43: =(I$40/(I$10^2))*((PI()^2)/4)*(I$12*100/I$39)*(((SIN(I35))^2)/((I$5+I$11*I$6)/I$11)^2) -> 0.37511095 | J43: =(J$40/(J$10^2))*((PI()^2)/4)*(J$12*100/J$39)*(((SIN(J35))^2)/((J$5+J$11*J$6)/J$11)^2) -> 0.37511095 | ... CG43: =(CG$40/(CG$10^2))*((PI()^2)/4)*(CG$12*100/CG$39)*(((SIN(CG35))^2)/((CG$5+CG$11*CG$6)/CG$11)^2) -> 0.37511095
...

Sheet CC
C3: 0 | D3: 1 | E3: 2 | F3: 3 | G3: 4 | H3: 5 | I3: 6 | J3: 7 | K3: PI/4 | L3: 8 | M3: 9 | N3: 10 | O3: PI/3 | P3: 11 | Q3: 12 | R3: 13 | S3: 14 | T3: 15 | U3: PI/2 | V3: 16 | W3: 17 | X3: 18 | Y3: 19 | Z3: 20 | AA3: 2*PI/3 | AB3: 21 | AC3: 22 | AD3: 23 | AE3: 3*PI/4 | AF3: 24 | AG3: 25 | AH3: 26 | AI3: 27 | AJ3: 28 | AK3: 29 | AL3: 30 | AM3: 31
B4: θ | C4: =C3*PI()/MAX($C3:$AM3) -> 0 | D4: =D3*PI()/MAX($C3:$AM3) -> 0.1013417 | E4: =E3*PI()/MAX($C3:$AM3) -> 0.2026834 | F4: =F3*PI()/MAX($C3:$AM3) -> 0.3040251 | G4: =G3*PI()/MAX($C3:$AM3) -> 0.40536679 | H4: =H3*PI()/MAX($C3:$AM3) -> 0.50670849 | I4: =I3*PI()/MAX($C3:$AM3) -> 0.60805019 | J4: =J3*PI()/MAX($C3:$AM3) -> 0.70939189 | K4: =PI()/4 -> 0.78539816 | L4: =L3*PI()/MAX($C3:$AM3) -> 0.81073359 | M4: =M3*PI()/MAX($C3:$AM3) -> 0.91207529 | N4: =N3*PI()/MAX($C3:$AM3) -> 1.013417 | O4: =PI()/3 -> 1.0471976 | P4: =P3*PI()/MAX($C3:$AM3) -> 1.1147587 | Q4: =Q3*PI()/MAX($C3:$AM3) -> 1.2161004 | R4: =R3*PI()/MAX($C3:$AM3) -> 1.3174421 | S4: =S3*PI()/MAX($C3:$AM3) -> 1.4187838 | T4: =T3*PI()/MAX($C3:$AM3) -> 1.5201255 | U4: =PI()/2 -> 1.5707963 | V4: =V3*PI()/MAX($C3:$AM3) -> 1.6214672 | W4: =W3*PI()/MAX($C3:$AM3) -> 1.7228089 | X4: =X3*PI()/MAX($C3:$AM3) -> 1.8241506 | Y4: =Y3*PI()/MAX($C3:$AM3) -> 1.9254923 | Z4: =Z3*PI()/MAX($C3:$AM3) -> 2.026834 | AA4: =2*PI()/3 -> 2.0943951 | AB4: =AB3*PI()/MAX($C3:$AM3) -> 2.1281757 | AC4: =AC3*PI()/MAX($C3:$AM3) -> 2.2295174 | AD4: =AD3*PI()/MAX($C3:$AM3) -> 2.3308591 | AE4: =3*PI()/4 -> 2.3561945 | AF4: =AF3*PI()/MAX($C3:$AM3) -> 2.4322008 | AG4: =AG3*PI()/MAX($C3:$AM3) -> 2.5335425 | AH4: =AH3*PI()/MAX($C3:$AM3) -> 2.6348842 | AI4: =AI3*PI()/MAX($C3:$AM3) -> 2.7362259 | AJ4: =AJ3*PI()/MAX($C3:$AM3) -> 2.8375676 | AK4: =AK3*PI()/MAX($C3:$AM3) -> 2.9389093 | AL4: =AL3*PI()/MAX($C3:$AM3) -> 3.040251 | AM4: =AM3*PI()/MAX($C3:$AM3) -> 3.1415927
B5: V.out | C5: ='Design Spec'!$D$95 -> 25 | D5: ='Design Spec'!$D$95 -> 25 | E5: ='Design Spec'!$D$95 -> 25 | F5: ='Design Spec'!$D$95 -> 25 | G5: ='Design Spec'!$D$95 -> 25 | H5: ='Design Spec'!$D$95 -> 25 | I5: ='Design Spec'!$D$95 -> 25 | J5: ='Design Spec'!$D$95 -> 25 | ... AM5: ='Design Spec'!$D$95 -> 25
B6: V.f | C6: ='Design Spec'!$D$106 -> 0 | D6: ='Design Spec'!$D$106 -> 0 | E6: ='Design Spec'!$D$106 -> 0 | F6: ='Design Spec'!$D$106 -> 0 | G6: ='Design Spec'!$D$106 -> 0 | H6: ='Design Spec'!$D$106 -> 0 | I6: ='Design Spec'!$D$106 -> 0 | J6: ='Design Spec'!$D$106 -> 0 | ... AM6: ='Design Spec'!$D$106 -> 0
B7: Vin_min | C7: ='Design Spec'!$D$83 -> 173.24116 | D7: ='Design Spec'!$D$83 -> 173.24116 | E7: ='Design Spec'!$D$83 -> 173.24116 | F7: ='Design Spec'!$D$83 -> 173.24116 | G7: ='Design Spec'!$D$83 -> 173.24116 | H7: ='Design Spec'!$D$83 -> 173.24116 | I7: ='Design Spec'!$D$83 -> 173.24116 | J7: ='Design Spec'!$D$83 -> 173.24116 | ... AM7: ='Design Spec'!$D$83 -> 173.24116
B8: Vin_max | C8: ='Design Spec'!$D$79 -> 264 | D8: ='Design Spec'!$D$79 -> 264 | E8: ='Design Spec'!$D$79 -> 264 | F8: ='Design Spec'!$D$79 -> 264 | G8: ='Design Spec'!$D$79 -> 264 | H8: ='Design Spec'!$D$79 -> 264 | I8: ='Design Spec'!$D$79 -> 264 | J8: ='Design Spec'!$D$79 -> 264 | ... AM8: ='Design Spec'!$D$79 -> 264
B9: n | C9: =IF('Res. Tank Design'!$F$9,'Res. Tank Design'!$F$9,'Res. Tank Design'!$D$9) -> 7.4527 | D9: =IF('Res. Tank Design'!$F$9,'Res. Tank Design'!$F$9,'Res. Tank Design'!$D$9) -> 7.4527 | E9: =IF('Res. Tank Design'!$F$9,'Res. Tank Design'!$F$9,'Res. Tank Design'!$D$9) -> 7.4527 | F9: =IF('Res. Tank Design'!$F$9,'Res. Tank Design'!$F$9,'Res. Tank Design'!$D$9) -> 7.4527 | G9: =IF('Res. Tank Design'!$F$9,'Res. Tank Design'!$F$9,'Res. Tank Design'!$D$9) -> 7.4527 | H9: =IF('Res. Tank Design'!$F$9,'Res. Tank Design'!$F$9,'Res. Tank Design'!$D$9) -> 7.4527 | I9: =IF('Res. Tank Design'!$F$9,'Res. Tank Design'!$F$9,'Res. Tank Design'!$D$9) -> 7.4527 | J9: =IF('Res. Tank Design'!$F$9,'Res. Tank Design'!$F$9,'Res. Tank Design'!$D$9) -> 7.4527 | ... AM9: =IF('Res. Tank Design'!$F$9,'Res. Tank Design'!$F$9,'Res. Tank Design'!$D$9) -> 7.4527
B10: Po-100% | C10: ='Design Spec'!$D$98 -> 657.5 | D10: ='Design Spec'!$D$98 -> 657.5 | E10: ='Design Spec'!$D$98 -> 657.5 | F10: ='Design Spec'!$D$98 -> 657.5 | G10: ='Design Spec'!$D$98 -> 657.5 | H10: ='Design Spec'!$D$98 -> 657.5 | I10: ='Design Spec'!$D$98 -> 657.5 | J10: ='Design Spec'!$D$98 -> 657.5 | ... AM10: ='Design Spec'!$D$98 -> 657.5
B11: Po-75% | C11: =C10/4*3 -> 493.125 | D11: =D10/4*3 -> 493.125 | E11: =E10/4*3 -> 493.125 | F11: =F10/4*3 -> 493.125 | G11: =G10/4*3 -> 493.125 | H11: =H10/4*3 -> 493.125 | I11: =I10/4*3 -> 493.125 | J11: =J10/4*3 -> 493.125 | ... AM11: =AM10/4*3 -> 493.125
B12: Po-50% | C12: =C10/2 -> 328.75 | D12: =D10/2 -> 328.75 | E12: =E10/2 -> 328.75 | F12: =F10/2 -> 328.75 | G12: =G10/2 -> 328.75 | H12: =H10/2 -> 328.75 | I12: =I10/2 -> 328.75 | J12: =J10/2 -> 328.75 | ... AM12: =AM10/2 -> 328.75
B13: Po-25% | C13: =C10/4 -> 164.375 | D13: =D10/4 -> 164.375 | E13: =E10/4 -> 164.375 | F13: =F10/4 -> 164.375 | G13: =G10/4 -> 164.375 | H13: =H10/4 -> 164.375 | I13: =I10/4 -> 164.375 | J13: =J10/4 -> 164.375 | ... AM13: =AM10/4 -> 164.375
B14: Pinst | C14: =2*'Design Spec'!$D$98*SIN(C4)^2 -> 0 | D14: =2*'Design Spec'!$D$98*SIN(D4)^2 -> 13.459064 | E14: =2*'Design Spec'!$D$98*SIN(E4)^2 -> 53.285239 | F14: =2*'Design Spec'!$D$98*SIN(F4)^2 -> 117.84804 | G14: =2*'Design Spec'!$D$98*SIN(G4)^2 -> 204.50425 | H14: =2*'Design Spec'!$D$98*SIN(H4)^2 -> 309.70616 | I14: =2*'Design Spec'!$D$98*SIN(I4)^2 -> 429.1468 | J14: =2*'Design Spec'!$D$98*SIN(J4)^2 -> 557.93624 | ... AM14: =2*'Design Spec'!$D$98*SIN(AM4)^2 -> 1.9738002e-29
B15: Iout.inst | C15: =C14/C5 -> 0 | D15: =D14/D5 -> 0.53836255 | E15: =E14/E5 -> 2.1314096 | F15: =F14/F5 -> 4.7139215 | G15: =G14/G5 -> 8.18017 | H15: =H14/H5 -> 12.388247 | I15: =I14/I5 -> 17.165872 | J15: =J14/J5 -> 22.317449 | ... AM15: =AM14/AM5 -> 7.8952008e-31
B17: V.out | C17: ='Design Spec'!$D$95 -> 25
B18: n | C18: =IF('Res. Tank Design'!$F$9,'Res. Tank Design'!$F$9,'Res. Tank Design'!$D$9) -> 7.4527
B20: @Vinmin | C20: PI/4 | D20: PI/3 | E20: PI/2
B21: fsw | C21: =RTC!BC152 -> 100.55807 | D21: =RTC!BC151 -> 104.54363 | E21: =RTC!BC149 -> 108.48953
B22: fr | C22: ='Res. Tank Design'!$D$55 -> 151.74828 | D22: ='Res. Tank Design'!$D$55 -> 151.74828 | E22: ='Res. Tank Design'!$D$55 -> 151.74828
B23: Iout.inst | C23: =2*'Design Spec'!$D$98/'Design Spec'!$D$95*SIN(PI()/4)^2 -> 26.3 | D23: =2*'Design Spec'!$D$98/'Design Spec'!$D$95*SIN(PI()/3)^2 -> 39.45 | E23: =2*'Design Spec'!$D$98/'Design Spec'!$D$95*SIN(PI()/2)^2 -> 52.6
B24: Isec.pk.tsw | C24: =PI()*(C22/C21)*C23*(1-COS(PI()*C22/IF(C21<C22,C22,C21)))^(-1) -> 62.342252 | D24: =PI()*(D22/D21)*D23*(1-COS(PI()*D22/IF(D21<D22,D22,D21)))^(-1) -> 89.948325 | E24: =PI()*(E22/E21)*E23*(1-COS(PI()*E22/IF(E21<E22,E22,E21)))^(-1) -> 115.56906
B25: Isec.rms.tsw (per winding) | C25: =IF('Design Spec'!$D$107=1,C24/2,C24/SQRT(2)) -> 31.171126 | D25: =IF('Design Spec'!$D$107=1,D24/2,D24/SQRT(2)) -> 44.974163 | E25: =IF('Design Spec'!$D$107=1,E24/2,E24/SQRT(2)) -> 57.78453
B26: Idiode.rms.tsw (per diode) | C26: =IF('Design Spec'!$D$107=1,C25,C25/SQRT(2)) -> 31.171126 | D26: =IF('Design Spec'!$D$108=1,D25,D25/SQRT(2)) -> 31.801535 | E26: =IF('Design Spec'!$D$108=1,E25,E25/SQRT(2)) -> 40.859833
B27: Itrafo.pk.tsw | C27: =C24/$C$18 -> 8.3650559 | D27: =D24/$C$18 -> 12.069227 | E27: =E24/$C$18 -> 15.507005
B28: Ilm.pk.tsw (trapezoidal) | C28: =0.5*(0.5*$C$17*$C$18)/(IF('Res. Tank Design'!$F$45,'Res. Tank Design'!$F$45,'Res. Tank Design'!$D$45)*IF(C21<C22,C22,C21))*1000 -> 12.789649 | D28: =0.5*(0.5*$C$17*$C$18)/(IF('Res. Tank Design'!$F$45,'Res. Tank Design'!$F$45,'Res. Tank Design'!$D$45)*IF(D21<D22,D22,D21))*1000 -> 12.789649 | E28: =0.5*(0.5*$C$17*$C$18)/(IF('Res. Tank Design'!$F$45,'Res. Tank Design'!$F$45,'Res. Tank Design'!$D$45)*IF(E21<E22,E22,E21))*1000 -> 12.789649
B29: Ipri.rms.tsw | C29: =SQRT(C27^2/2+C28^2/3+(C28*C21*(1/C21-1/C22))^2) -> 10.398379 | D29: =SQRT(D27^2/2+D28^2/3+(D28*D21*(1/D21-1/D22))^2) -> 11.966062 | E29: =SQRT(E27^2/2+E28^2/3+(E28*E21*(1/E21-1/E22))^2) -> 13.713187
B30: Imos.rms.tsw (per mos) | C30: =C29/SQRT(2) -> 7.3527643 | D30: =D29/SQRT(2) -> 8.4612835 | E30: =E29/SQRT(2) -> 9.6966872
B31: Icout.rms | C31: =SQRT(0.5*IF(C21>C22,C22,C21)/C22*(C24^2)-C23^2) -> 24.414131
B33: @Vinmax | C33: PI/4 | D33: PI/3 | E33: PI/2
B34: fsw | C34: =RTC!BC200 -> 117.75405 | D34: =RTC!BC199 -> 133.06125 | E34: =RTC!BC197 -> 152.08937
B35: fr | C35: ='Res. Tank Design'!$D$55 -> 151.74828 | D35: ='Res. Tank Design'!$D$55 -> 151.74828 | E35: ='Res. Tank Design'!$D$55 -> 151.74828
B36: Iout.inst | C36: =2*'Design Spec'!$D$98/'Design Spec'!$D$95*SIN(PI()/4)^2 -> 26.3 | D36: =2*'Design Spec'!$D$98/'Design Spec'!$D$95*SIN(PI()/3)^2 -> 39.45 | E36: =2*'Design Spec'!$D$98/'Design Spec'!$D$95*SIN(PI()/2)^2 -> 52.6
B37: Isec.pk.tsw | C37: =PI()*(C35/C34)*C36*(1-COS(PI()*C35/IF(C34<C35,C35,C34)))^(-1) -> 53.238225 | D37: =PI()*(D35/D34)*D36*(1-COS(PI()*D35/IF(D34<D35,D35,D34)))^(-1) -> 70.67065 | E37: =PI()*(E35/E34)*E36*(1-COS(PI()*E35/IF(E34<E35,E35,E34)))^(-1) -> 82.439612
B38: Isec.rms.tsw (per winding) | C38: =IF('Design Spec'!$D$107=1,C37/2,C37/SQRT(2)) -> 26.619113 | D38: =IF('Design Spec'!$D$107=1,D37/2,D37/SQRT(2)) -> 35.335325 | E38: =IF('Design Spec'!$D$107=1,E37/2,E37/SQRT(2)) -> 41.219806
B39: Idiode.rms.tsw (per diode) | C39: =IF('Design Spec'!$D$107=1,C38,C38/SQRT(2)) -> 26.619113 | D39: =IF('Design Spec'!$D$108=1,D38,D38/SQRT(2)) -> 24.985848 | E39: =IF('Design Spec'!$D$108=1,E38,E38/SQRT(2)) -> 29.146804
B40: Itrafo.pk.tsw | C40: =C37/$C$18 -> 7.1434816 | D40: =D37/$C$18 -> 9.4825566 | E40: =E37/$C$18 -> 11.061711
B41: Ilm.pk.tsw (trapezoidal) | C41: =0.5*(0.5*$C$17*$C$18)/(IF('Res. Tank Design'!$F$45,'Res. Tank Design'!$F$45,'Res. Tank Design'!$D$45)*IF(C34<C35,C35,C34))*1000 -> 12.789649 | D41: =0.5*(0.5*$C$17*$C$18)/(IF('Res. Tank Design'!$F$45,'Res. Tank Design'!$F$45,'Res. Tank Design'!$D$45)*IF(D34<D35,D35,D34))*1000 -> 12.789649 | E41: =0.5*(0.5*$C$17*$C$18)/(IF('Res. Tank Design'!$F$45,'Res. Tank Design'!$F$45,'Res. Tank Design'!$D$45)*IF(E34<E35,E35,E34))*1000 -> 12.760966
B42: Ipri.rms.tsw | C42: =SQRT(C40^2/2+C41^2/3+(C41*C34*(1/C34-1/C35))^2) -> 9.3940681 | D42: =SQRT(D40^2/2+D41^2/3+(D41*D34*(1/D34-1/D35))^2) -> 10.097774 | E42: =SQRT(E40^2/2+E41^2/3+(E41*E34*(1/E34-1/E35))^2) -> 10.745338
B43: Imos.rms.tsw (per mos) | C43: =C42/SQRT(2) -> 6.6426093 | D43: =D42/SQRT(2) -> 7.1402047 | E43: =E42/SQRT(2) -> 7.5981017
B44: Icout.rms | C44: =SQRT(0.5*IF(C34>C35,C35,C34)/C35*(C37^2)-C36^2) -> 20.198942
B46: @Vinnom | C46: PI/4 | D46: PI/3 | E46: PI/2
...

Sheet OutCap_Sel_DB
A1: Case Size Table and Permissible Ripple Current | I1: Multicomp PRO MCLPR Series
A3: W.V. | B3: Cap.(μF) | C3: Case Size ØD [mm] | D3: Case Size L [mm] | E3: R.C. [A rms] | F3: tan(delta) | G3: Estimated ESR | H3: Volume cm3 | I3: Cap/Vol | J3: Energy/Vol maximum | L3: Energy/Vol suitable cap | M3: Total volume | N3: Min | O3: W.V. | P3: Cap.(μF) | Q3: Case Size ØD [mm] | R3: Case Size L [mm] | S3: ESR | U3: Expected cap volume [cm3] | V3: W.V. | W3: Cap.(μF) | X3: Case Size ØD [mm] | Y3: Case Size L [mm] | Z3: ESR | AA3: Number of caps | AB3: Volume check
A4: 25 | B4: 3300 | C4: 20 | D4: 30 | E4: 2.05 | F4: 0.2 | G4: =F4/(2*PI()*120*B4*10^-6) -> 0.080381284 | H4: =0.001*D4*PI()*(C4/2)^2 -> 9.424778 | I4: =B4/H4 -> 350.14087 | J4: =0.5*I4*A4^2 -> 109419.02 | L4: =IF(AND($W$9<A4,D4<=$W$14),0.5*I4*$W$7,"") | M4: =IF(L4<>"",ROUNDUP($W$12/B4,0)*H4,"") | N4: =IF(M4=MIN($M$4:$M$266),M4,"") | O4: =IF($N4=MIN($M$4:$M$266),A4,"") | P4: =IF($N4=MIN($M$4:$M$266),B4,"") | Q4: =IF($N4=MIN($M$4:$M$266),C4,"") | R4: =IF($N4=MIN($M$4:$M$266),D4,"") | S4: =IF($N4=MIN($M$4:$M$266),G4,"") | U4: =IF(MAX(N4:N266)<>0,MAX(N4:N266),"") -> 141.37167 | V4: =IF(MAX(O4:O266)<>0,MAX(O4:O266),"") -> 50 | W4: =IF(MAX(P4:P266)<>0,MAX(P4:P266),"") -> 4700 | X4: =IF(MAX(Q4:Q266)<>0,MAX(Q4:Q266),"") -> 30 | Y4: =IF(MAX(R4:R266)<>0,MAX(R4:R266),"") -> 25 | Z4: =IF(MAX(S4:S266)<>0,MAX(S4:S266),"") -> 0.084656885 | AA4: =IF(W4<>"",ROUNDUP(W12/W4,0),"") -> 8 | AB4: =0.001*AA4*Y4*PI()*(X4/2)^2 -> 141.37167
A5: 25 | B5: 3300 | C5: 22 | D5: 25 | E5: 2.1 | F5: 0.2 | G5: =F5/(2*PI()*120*B5*10^-6) -> 0.080381284 | H5: =0.001*D5*PI()*(C5/2)^2 -> 9.5033178 | I5: =B5/H5 -> 347.24715 | J5: =0.5*I5*A5^2 -> 108514.73 | L5: =IF(AND($W$9<A5,D5<=$W$14),0.5*I5*$W$7,"") | M5: =IF(L5<>"",ROUNDUP($W$12/B5,0)*H5,"") | N5: =IF(M5=MIN($M$4:$M$266),M5,"") | O5: =IF($N5=MIN($M$4:$M$266),A5,"") | P5: =IF($N5=MIN($M$4:$M$266),B5,"") | Q5: =IF($N5=MIN($M$4:$M$266),C5,"") | R5: =IF($N5=MIN($M$4:$M$266),D5,"") | S5: =IF($N5=MIN($M$4:$M$266),G5,"")
A6: 25 | B6: 4700 | C6: 20 | D6: 30 | E6: 2.5 | F6: 0.3 | G6: =F6/(2*PI()*120*B6*10^-6) -> 0.084656885 | H6: =0.001*D6*PI()*(C6/2)^2 -> 9.424778 | I6: =B6/H6 -> 498.68549 | J6: =0.5*I6*A6^2 -> 155839.22 | L6: =IF(AND($W$9<A6,D6<=$W$14),0.5*I6*$W$7,"") | M6: =IF(L6<>"",ROUNDUP($W$12/B6,0)*H6,"") | N6: =IF(M6=MIN($M$4:$M$266),M6,"") | O6: =IF($N6=MIN($M$4:$M$266),A6,"") | P6: =IF($N6=MIN($M$4:$M$266),B6,"") | Q6: =IF($N6=MIN($M$4:$M$266),C6,"") | R6: =IF($N6=MIN($M$4:$M$266),D6,"") | S6: =IF($N6=MIN($M$4:$M$266),G6,"")
A7: 25 | B7: 4700 | C7: 22 | D7: 25 | E7: 2.2 | F7: 0.3 | G7: =F7/(2*PI()*120*B7*10^-6) -> 0.084656885 | H7: =0.001*D7*PI()*(C7/2)^2 -> 9.5033178 | I7: =B7/H7 -> 494.56412 | J7: =0.5*I7*A7^2 -> 154551.29 | L7: =IF(AND($W$9<A7,D7<=$W$14),0.5*I7*$W$7,"") | M7: =IF(L7<>"",ROUNDUP($W$12/B7,0)*H7,"") | N7: =IF(M7=MIN($M$4:$M$266),M7,"") | O7: =IF($N7=MIN($M$4:$M$266),A7,"") | P7: =IF($N7=MIN($M$4:$M$266),B7,"") | Q7: =IF($N7=MIN($M$4:$M$266),C7,"") | R7: =IF($N7=MIN($M$4:$M$266),D7,"") | S7: =IF($N7=MIN($M$4:$M$266),G7,"") | U7: Output voltage | W7: ='Design Spec'!D95 -> 25 | X7: link
A8: 25 | B8: 5600 | C8: 22 | D8: 31 | E8: 2.6 | F8: 0.3 | G8: =F8/(2*PI()*120*B8*10^-6) -> 0.071051314 | H8: =0.001*D8*PI()*(C8/2)^2 -> 11.784114 | I8: =B8/H8 -> 475.21604 | J8: =0.5*I8*A8^2 -> 148505.01 | L8: =IF(AND($W$9<A8,D8<=$W$14),0.5*I8*$W$7,"") | M8: =IF(L8<>"",ROUNDUP($W$12/B8,0)*H8,"") | N8: =IF(M8=MIN($M$4:$M$266),M8,"") | O8: =IF($N8=MIN($M$4:$M$266),A8,"") | P8: =IF($N8=MIN($M$4:$M$266),B8,"") | Q8: =IF($N8=MIN($M$4:$M$266),C8,"") | R8: =IF($N8=MIN($M$4:$M$266),D8,"") | S8: =IF($N8=MIN($M$4:$M$266),G8,"") | U8: Ripple pk-pk | W8: ='Design Spec'!D97 -> 10
A9: 25 | B9: 6800 | C9: 22 | D9: 30 | E9: 2.85 | F9: 0.3 | G9: =F9/(2*PI()*120*B9*10^-6) -> 0.058512847 | H9: =0.001*D9*PI()*(C9/2)^2 -> 11.403981 | I9: =B9/H9 -> 596.28298 | J9: =0.5*I9*A9^2 -> 186338.43 | L9: =IF(AND($W$9<A9,D9<=$W$14),0.5*I9*$W$7,"") | M9: =IF(L9<>"",ROUNDUP($W$12/B9,0)*H9,"") | N9: =IF(M9=MIN($M$4:$M$266),M9,"") | O9: =IF($N9=MIN($M$4:$M$266),A9,"") | P9: =IF($N9=MIN($M$4:$M$266),B9,"") | Q9: =IF($N9=MIN($M$4:$M$266),C9,"") | R9: =IF($N9=MIN($M$4:$M$266),D9,"") | S9: =IF($N9=MIN($M$4:$M$266),G9,"") | U9: Maximum output voltage | W9: =W7+0.5*W7*W8/100+5 -> 31.25
A10: 25 | B10: 6800 | C10: 25 | D10: 26 | E10: 2.7 | F10: 0.3 | G10: =F10/(2*PI()*120*B10*10^-6) -> 0.058512847 | H10: =0.001*D10*PI()*(C10/2)^2 -> 12.76272 | I10: =B10/H10 -> 532.80178 | J10: =0.5*I10*A10^2 -> 166500.56 | L10: =IF(AND($W$9<A10,D10<=$W$14),0.5*I10*$W$7,"") | M10: =IF(L10<>"",ROUNDUP($W$12/B10,0)*H10,"") | N10: =IF(M10=MIN($M$4:$M$266),M10,"") | O10: =IF($N10=MIN($M$4:$M$266),A10,"") | P10: =IF($N10=MIN($M$4:$M$266),B10,"") | Q10: =IF($N10=MIN($M$4:$M$266),C10,"") | R10: =IF($N10=MIN($M$4:$M$266),D10,"") | S10: =IF($N10=MIN($M$4:$M$266),G10,"") | U10: Min cap for ripple pk-pk | W10: ='Power Components'!D21 -> 35623.617 | X10: link
